Workbook

Sheet Boletim_do_Veiculo_2026-09-08_2
A1: PLACA | B1: PREFIXO | C1: UO | D1: MOTORISTAS | E1: DIA | F1: DISTÂNCIA PERCORRIDA | G1: TEMPO IGNIÇÃO LIGADA | H1: TEMPO EM VIGENCIA | I1: EXCESSO DE VELOCIDADE | J1: ACELERAÇÃO BRUSCA | K1: FRENAGEM BRUSCA | L1: FRENAGEM BRUSCA SEM ACIONAMENTO DO PEDAL | M1: FRENAGEM BRUSCA COM ACIONAMENTO DO PEDAL | N1: CURVA BRUSCA | O1: BANGUELA | P1: PARADO LIGADO | Q1: CONSUMO DE COMBUSTIVEL | R1: MÉDIA CONSUMO | S1: RPM MARCHA LENTA | T1: RPM ABAIXO DA VERDE | U1: RPM VERDE (ECONÔMICO) | V1: RPM VERDE (POTÊNCIA) | W1: RPM AMARELO | X1: RPM VERMELHO | Y1: EXCESSO DE RPM | Z1: PEDAL ACIONADO FAIXA 1 | AA1: PEDAL ACIONADO FAIXA 2 | AB1: PEDAL ACIONADO FAIXA 3 | AC1: LOGRADOURO INICIAL | AD1: LOGRADOURO FINAL | AE1: HODOMETRO INICIAL | AF1: HODOMETRO FINAL | AG1: TEMPO EM MOVIMENTO | AH1: TEMPO PARADO | AI1: TEMPO COM GPS INVALIDO | AJ1: TEMPO EQUIP DESLIGADO | AK1: TEMPO BATENDO TRANSMISSÃO | AL1: TEMPO FREIO MOTOR | AM1: CHECKLIST | AN1: SEM CINTO | AO1: BOCEJO | AP1: SEM MOTORISTA | AQ1: USO DE CIGARRO | AR1: DISTRAÇÃO | AS1: FADIGA | AT1: USO DE CELULAR | AU1: DISTÂNCIA PERIGOSA | AV1: CÂMERA OBSTRUÍDA | AW1: ULTRAPASSAGEM ILEGAL | AX1: SEM CONE | AY1: SEM ÓCULOS DE EPI | AZ1: SEM LUVAS | BA1: CARONA | BB1: DESCONEXÃO DA CÂMERA DE AUDITORIA | BC1: DESCONEXÃO DA CÂMERA DO MOTORISTA | BD1: DESCONEXÃO DA CÂMERA DA PISTA | BE1: USO INDEVIDO DE VEÍCULO | BF1: TEMPO USO INDEVIDO DE VEÍCULO | BG1: MANUSEIO DE OBJETO | BH1: PARADA INCOMPLETA | BI1: NÃO PAROU | BJ1: SEM CASQUETE | BK1: DESVIO DE ROTA | BM1: Distância (km) - todos os dias | BN1: Consumo (L) - dias com reporte | BO1: Média (Km/L) - dias com reporte | BP1: Distância (km) - dias com reporte | BQ1: Tracinho (1=sem reporte telemetria)
A2: JQC9385 | B2: R5115 | C2: ROTA TRANSPORTES - ITABUNA | D2: WILSON DE SOUSA LEAL - 70853592500, ALEGUIRINALDO DE SOUZA LEITE JUNIOR - 05053784507 | E2: 46273 | F2: 126.33 | G2: 0.29738426 | H2: 0.29380787 | I2: 0.00017361111 | J2: 1 | K2: 0 | L2: 0 | M2: 0 | N2: 0 | O2: 0 | P2: 0 | Q2: - | R2: - | S2: 0 | T2: 0 | U2: 0 | V2: 0 | W2: 0 | X2: 0 | Y2: 0 | Z2: 0 | AA2: 0 | AB2: 0 | AC2: Rua K | AD2: Avenida Amélia Amado | AE2: 91534.21 | AF2: 91660.54 | AG2: 0.26135417 | AH2: 0.14390046 | AI2: 0 | AJ2: 0 | AK2: 0 | AL2: 0 | AM2: N/A | AN2: 0 | AO2: 0 | AP2: 0 | AQ2: 0 | AR2: 0 | AS2: 0 | AT2: 0 | AU2: 9 | AV2: 0 | AW2: 0 | AX2: 0 | AY2: 0 | AZ2: 0 | BA2: 0 | BB2: 0 | BC2: 0 | BD2: 0 | BE2: 0 | BF2: 0 | BG2: 0 | BH2: 0 | BI2: 0 | BJ2: 0 | BK2: 0 | BM2: =IFERROR(VALUE(F2),"") -> 126.33 | BN2: =IF(R2="-","",IFERROR(VALUE(LEFT(Q2,LEN(Q2)-2)),"")) | BO2: =IF(R2="-","",IFERROR(VALUE(LEFT(R2,LEN(R2)-5)),"")) | BP2: =IF(R2="-","",IFERROR(VALUE(F2),"")) | BQ2: =IF(R2="-",1,0) -> 1
A3: JQC9385 | B3: R5115 | C3: ROTA TRANSPORTES - ITABUNA | D3: WILSON DE SOUSA LEAL - 70853592500, RAFAEL DE JESUS BARRETO - 85830111500 | E3: 46274 | F3: 106.06 | G3: 0.28118056 | H3: 0.27314815 | I3: 9.2592593e-05 | J3: 0 | K3: 1 | L3: 0 | M3: 0 | N3: 1 | O3: 0 | P3: 0 | Q3: - | R3: - | S3: 0 | T3: 0 | U3: 0 | V3: 0 | W3: 0 | X3: 0 | Y3: 0 | Z3: 0 | AA3: 0 | AB3: 0 | AC3: Rua Castro Alves | AD3: Avenida Amélia Amado | AE3: 91660.54 | AF3: 91766.60 | AG3: 0.22017361 | AH3: 0.14052083 | AI3: 0 | AJ3: 0 | AK3: 0 | AL3: 0 | AM3: N/A | AN3: 0 | AO3: 0 | AP3: 0 | AQ3: 0 | AR3: 0 | AS3: 0 | AT3: 0 | AU3: 2 | AV3: 0 | AW3: 0 | AX3: 0 | AY3: 0 | AZ3: 0 | BA3: 0 | BB3: 0 | BC3: 0 | BD3: 0 | BE3: 0 | BF3: 0 | BG3: 0 | BH3: 0 | BI3: 0 | BJ3: 0 | BK3: 0 | BM3: =IFERROR(VALUE(F3),"") -> 106.06 | BN3: =IF(R3="-","",IFERROR(VALUE(LEFT(Q3,LEN(Q3)-2)),"")) | BO3: =IF(R3="-","",IFERROR(VALUE(LEFT(R3,LEN(R3)-5)),"")) | BP3: =IF(R3="-","",IFERROR(VALUE(F3),"")) | BQ3: =IF(R3="-",1,0) -> 1
A4: JQC9385 | B4: R5115 | C4: ROTA TRANSPORTES - ITABUNA | D4: WILSON DE SOUSA LEAL - 70853592500 | E4: 46275 | F4: 104.03 | G4: 0.23736111 | H4: 0.22246528 | I4: 4.6296296e-05 | J4: 0 | K4: 0 | L4: 0 | M4: 0 | N4: 0 | O4: 0 | P4: 0 | Q4: - | R4: - | S4: 0 | T4: 0 | U4: 0 | V4: 0 | W4: 0 | X4: 0 | Y4: 0 | Z4: 0 | AA4: 0 | AB4: 0 | AC4: Rua K | AD4: Avenida Amélia Amado | AE4: 91766.60 | AF4: 91870.63 | AG4: 0.205 | AH4: 0.14122685 | AI4: 0 | AJ4: 0 | AK4: 0 | AL4: 0 | AM4: N/A | AN4: 0 | AO4: 0 | AP4: 0 | AQ4: 0 | AR4: 0 | AS4: 1 | AT4: 0 | AU4: 5 | AV4: 0 | AW4: 0 | AX4: 0 | AY4: 0 | AZ4: 0 | BA4: 0 | BB4: 0 | BC4: 0 | BD4: 0 | BE4: 0 | BF4: 0 | BG4: 0 | BH4: 0 | BI4: 0 | BJ4: 0 | BK4: 0 | BM4: =IFERROR(VALUE(F4),"") -> 104.03 | BN4: =IF(R4="-","",IFERROR(VALUE(LEFT(Q4,LEN(Q4)-2)),"")) | BO4: =IF(R4="-","",IFERROR(VALUE(LEFT(R4,LEN(R4)-5)),"")) | BP4: =IF(R4="-","",IFERROR(VALUE(F4),"")) | BQ4: =IF(R4="-",1,0) -> 1
A5: JQC9385 | B5: R5115 | C5: ROTA TRANSPORTES - ITABUNA | D5: WILSON DE SOUSA LEAL - 70853592500 | E5: 46276 | F5: 104.35 | G5: 0.27340278 | H5: 0.26832176 | I5: 9.2592593e-05 | J5: 1 | K5: 0 | L5: 0 | M5: 0 | N5: 0 | O5: 0 | P5: 0 | Q5: - | R5: - | S5: 0 | T5: 0 | U5: 0 | V5: 0 | W5: 0 | X5: 0 | Y5: 0 | Z5: 0 | AA5: 0 | AB5: 0 | AC5: Rua K | AD5: Avenida Amélia Amado | AE5: 91870.63 | AF5: 91974.98 | AG5: 0.21420139 | AH5: 0.11803241 | AI5: 0 | AJ5: 0 | AK5: 0 | AL5: 0 | AM5: N/A | AN5: 0 | AO5: 0 | AP5: 0 | AQ5: 0 | AR5: 0 | AS5: 0 | AT5: 0 | AU5: 7 | AV5: 0 | AW5: 0 | AX5: 0 | AY5: 0 | AZ5: 0 | BA5: 0 | BB5: 0 | BC5: 0 | BD5: 0 | BE5: 0 | BF5: 0 | BG5: 0 | BH5: 0 | BI5: 0 | BJ5: 0 | BK5: 0 | BM5: =IFERROR(VALUE(F5),"") -> 104.35 | BN5: =IF(R5="-","",IFERROR(VALUE(LEFT(Q5,LEN(Q5)-2)),"")) | BO5: =IF(R5="-","",IFERROR(VALUE(LEFT(R5,LEN(R5)-5)),"")) | BP5: =IF(R5="-","",IFERROR(VALUE(F5),"")) | BQ5: =IF(R5="-",1,0) -> 1
A6: JQC9385 | B6: R5115 | C6: ROTA TRANSPORTES - ITABUNA | D6: WILSON DE SOUSA LEAL - 70853592500, RENILDO FREITAS PEREIRA - 40936805587 | E6: 46277 | F6: 81.95 | G6: 0.22818287 | H6: 0.224375 | I6: 5.787037e-05 | J6: 0 | K6: 0 | L6: 0 | M6: 0 | N6: 1 | O6: 0 | P6: 0 | Q6: - | R6: - | S6: 0 | T6: 0 | U6: 0 | V6: 0 | W6: 0 | X6: 0 | Y6: 0 | Z6: 0 | AA6: 0 | AB6: 0 | AC6: Rua K | AD6: Avenida Amélia Amado | AE6: 91974.98 | AF6: 92056.93 | AG6: 0.18332176 | AH6: 0.095983796 | AI6: 0 | AJ6: 0 | AK6: 0 | AL6: 0 | AM6: N/A | AN6: 0 | AO6: 0 | AP6: 0 | AQ6: 0 | AR6: 0 | AS6: 0 | AT6: 0 | AU6: 2 | AV6: 0 | AW6: 0 | AX6: 0 | AY6: 0 | AZ6: 0 | BA6: 0 | BB6: 0 | BC6: 0 | BD6: 0 | BE6: 0 | BF6: 0 | BG6: 0 | BH6: 0 | BI6: 0 | BJ6: 0 | BK6: 0 | BM6: =IFERROR(VALUE(F6),"") -> 81.95 | BN6: =IF(R6="-","",IFERROR(VALUE(LEFT(Q6,LEN(Q6)-2)),"")) | BO6: =IF(R6="-","",IFERROR(VALUE(LEFT(R6,LEN(R6)-5)),"")) | BP6: =IF(R6="-","",IFERROR(VALUE(F6),"")) | BQ6: =IF(R6="-",1,0) -> 1
A7: JQC9385 | B7: R5115 | C7: ROTA TRANSPORTES - ITABUNA | D7: WILSON DE SOUSA LEAL - 70853592500 | E7: 46279 | F7: 105.31 | G7: 0.25493056 | H7: 0.25422454 | I7: 0.00017361111 | J7: 0 | K7: 0 | L7: 0 | M7: 0 | N7: 2 | O7: 0 | P7: 0 | Q7: - | R7: - | S7: 0 | T7: 0 | U7: 0 | V7: 0 | W7: 0 | X7: 0 | Y7: 0 | Z7: 0 | AA7: 0 | AB7: 0 | AC7: Avenida Amélia Amado | AD7: Avenida Amélia Amado | AE7: 92056.93 | AF7: 92162.23 | AG7: 0.21837963 | AH7: 0.092094907 | AI7: 0 | AJ7: 0 | AK7: 0 | AL7: 0 | AM7: N/A | AN7: 0 | AO7: 0 | AP7: 0 | AQ7: 0 | AR7: 0 | AS7: 1 | AT7: 0 | AU7: 9 | AV7: 0 | AW7: 0 | AX7: 0 | AY7: 0 | AZ7: 0 | BA7: 0 | BB7: 0 | BC7: 0 | BD7: 0 | BE7: 0 | BF7: 0 | BG7: 0 | BH7: 0 | BI7: 0 | BJ7: 0 | BK7: 0 | BM7: =IFERROR(VALUE(F7),"") -> 105.31 | BN7: =IF(R7="-","",IFERROR(VALUE(LEFT(Q7,LEN(Q7)-2)),"")) | BO7: =IF(R7="-","",IFERROR(VALUE(LEFT(R7,LEN(R7)-5)),"")) | BP7: =IF(R7="-","",IFERROR(VALUE(F7),"")) | BQ7: =IF(R7="-",1,0) -> 1
A8: JQC9404 | B8: R5125 | C8: ROTA TRANSPORTES - ITABUNA | E8: 46273 | F8: 0.00 | G8: 0.011018519 | H8: 0 | I8: 0 | J8: 0 | K8: 0 | L8: 0 | M8: 0 | N8: 0 | O8: 0 | P8: 0 | Q8: - | R8: - | S8: 0 | T8: 0 | U8: 0 | V8: 0 | W8: 0 | X8: 0 | Y8: 0 | Z8: 0 | AA8: 0 | AB8: 0 | AC8: Avenida Amélia Amado | AD8: Rua K | AE8: 91485.00 | AF8: 91485.00 | AG8: 0.00087962963 | AH8: 0.011122685 | AI8: 0 | AJ8: 0 | AK8: 0 | AL8: 0 | AM8: N/A | AN8: 0 | AO8: 0 | AP8: 0 | AQ8: 0 | AR8: 0 | AS8: 0 | AT8: 0 | AU8: 0 | AV8: 0 | AW8: 0 | AX8: 0 | AY8: 0 | AZ8: 0 | BA8: 0 | BB8: 0 | BC8: 0 | BD8: 0 | BE8: 0 | BF8: 0 | BG8: 0 | BH8: 0 | BI8: 0 | BJ8: 0 | BK8: 0 | BM8: =IFERROR(VALUE(F8),"") -> 0 | BN8: =IF(R8="-","",IFERROR(VALUE(LEFT(Q8,LEN(Q8)-2)),"")) | BO8: =IF(R8="-","",IFERROR(VALUE(LEFT(R8,LEN(R8)-5)),"")) | BP8: =IF(R8="-","",IFERROR(VALUE(F8),"")) | BQ8: =IF(R8="-",1,0) -> 1
A9: JQC9414 | B9: R5155 | C9: ROTA TRANSPORTES - ITABUNA | D9: ISRAEL SOARES DOS SANTOS - 09628284916, EDVALDO ELIAS SILVA - 99881624568 | E9: 46273 | F9: 128.72 | G9: 0.32350694 | H9: 0.24025463 | I9: 0.00016203704 | J9: 0 | K9: 0 | L9: 0 | M9: 0 | N9: 2 | O9: 0 | P9: 0 | Q9: - | R9: - | S9: 0 | T9: 0 | U9: 0 | V9: 0 | W9: 0 | X9: 0 | Y9: 0 | Z9: 0 | AA9: 0 | AB9: 0 | AC9: Avenida Amélia Amado | AD9: - | AE9: 726636.49 | AF9: 726765.21 | AG9: 0.27494213 | AH9: 0.12979167 | AI9: 0 | AJ9: 0 | AK9: 0 | AL9: 0 | AM9: N/A | AN9: 0 | AO9: 0 | AP9: 0 | AQ9: 0 | AR9: 0 | AS9: 0 | AT9: 0 | AU9: 0 | AV9: 0 | AW9: 0 | AX9: 0 | AY9: 0 | AZ9: 0 | BA9: 0 | BB9: 0 | BC9: 0 | BD9: 0 | BE9: 0 | BF9: 0 | BG9: 0 | BH9: 0 | BI9: 0 | BJ9: 0 | BK9: 0 | BM9: =IFERROR(VALUE(F9),"") -> 128.72 | BN9: =IF(R9="-","",IFERROR(VALUE(LEFT(Q9,LEN(Q9)-2)),"")) | BO9: =IF(R9="-","",IFERROR(VALUE(LEFT(R9,LEN(R9)-5)),"")) | BP9: =IF(R9="-","",IFERROR(VALUE(F9),"")) | BQ9: =IF(R9="-",1,0) -> 1
A10: JQC9414 | B10: R5155 | C10: ROTA TRANSPORTES - ITABUNA | D10: ISRAEL SOARES DOS SANTOS - 09628284916, EDVALDO ELIAS SILVA - 99881624568 | E10: 46274 | F10: 148.75 | G10: 0.37881944 | H10: 0.28887731 | I10: 0.00025462963 | J10: 0 | K10: 2 | L10: 0 | M10: 0 | N10: 1 | O10: 0 | P10: 0 | Q10: - | R10: - | S10: 0 | T10: 0 | U10: 0 | V10: 0 | W10: 0 | X10: 0 | Y10: 0 | Z10: 0 | AA10: 0 | AB10: 0 | AC10: - | AD10: Avenida Amélia Amado | AE10: 726765.50 | AF10: 726914.25 | AG10: 0.30527778 | AH10: 0.19894676 | AI10: 0 | AJ10: 0 | AK10: 0 | AL10: 0 | AM10: N/A | AN10: 0 | AO10: 0 | AP10: 0 | AQ10: 0 | AR10: 0 | AS10: 0 | AT10: 0 | AU10: 1 | AV10: 0 | AW10: 0 | AX10: 0 | AY10: 0 | AZ10: 0 | BA10: 0 | BB10: 0 | BC10: 0 | BD10: 0 | BE10: 0 | BF10: 0 | BG10: 0 | BH10: 0 | BI10: 0 | BJ10: 0 | BK10: 0 | BM10: =IFERROR(VALUE(F10),"") -> 148.75 | BN10: =IF(R10="-","",IFERROR(VALUE(LEFT(Q10,LEN(Q10)-2)),"")) | BO10: =IF(R10="-","",IFERROR(VALUE(LEFT(R10,LEN(R10)-5)),"")) | BP10: =IF(R10="-","",IFERROR(VALUE(F10),"")) | BQ10: =IF(R10="-",1,0) -> 1
A11: JQC9414 | B11: R5155 | C11: ROTA TRANSPORTES - ITABUNA | D11: ISRAEL SOARES DOS SANTOS - 09628284916, EDVALDO ELIAS SILVA - 99881624568, EMERSON ANDRADE DA SILVA - 96170824549 | E11: 46275 | F11: 127.59 | G11: 0.29146991 | H11: 0.23175926 | I11: 0.0013425926 | J11: 0 | K11: 0 | L11: 0 | M11: 0 | N11: 2 | O11: 0 | P11: 0 | Q11: - | R11: - | S11: 0 | T11: 0 | U11: 0 | V11: 0 | W11: 0 | X11: 0 | Y11: 0 | Z11: 0 | AA11: 0 | AB11: 0 | AC11: Avenida Amélia Amado | AD11: - | AE11: 726914.25 | AF11: 727041.84 | AG11: 0.26199074 | AH11: 0.13716435 | AI11: 0 | AJ11: 0 | AK11: 0 | AL11: 0 | AM11: N/A | AN11: 0 | AO11: 0 | AP11: 0 | AQ11: 0 | AR11: 0 | AS11: 0 | AT11: 0 | AU11: 2 | AV11: 0 | AW11: 0 | AX11: 0 | AY11: 0 | AZ11: 0 | BA11: 0 | BB11: 0 | BC11: 0 | BD11: 0 | BE11: 0 | BF11: 0 | BG11: 0 | BH11: 0 | BI11: 0 | BJ11: 0 | BK11: 0 | BM11: =IFERROR(VALUE(F11),"") -> 127.59 | BN11: =IF(R11="-","",IFERROR(VALUE(LEFT(Q11,LEN(Q11)-2)),"")) | BO11: =IF(R11="-","",IFERROR(VALUE(LEFT(R11,LEN(R11)-5)),"")) | BP11: =IF(R11="-","",IFERROR(VALUE(F11),"")) | BQ11: =IF(R11="-",1,0) -> 1
A12: JQC9414 | B12: R5155 | C12: ROTA TRANSPORTES - ITABUNA | D12: ISRAEL SOARES DOS SANTOS - 09628284916, Jose Raimundo dos Santos - 00335224563, EDVALDO ELIAS SILVA - 99881624568, ERICO OLIVEIRA PEREIRA - 04284740555 | E12: 46276 | F12: 183.77 | G12: 0.42375 | H12: 0.32835648 | I12: 0.00016203704 | J12: 0 | K12: 3 | L12: 0 | M12: 0 | N12: 1 | O12: 0 | P12: 0 | Q12: - | R12: - | S12: 0 | T12: 0 | U12: 0 | V12: 0 | W12: 0 | X12: 0 | Y12: 0 | Z12: 0 | AA12: 0 | AB12: 0 | AC12: - | AD12: BR-415 | AE12: 727042.08 | AF12: 727225.86 | AG12: 0.36813657 | AH12: 0.16981481 | AI12: 0 | AJ12: 0 | AK12: 0 | AL12: 0 | AM12: N/A | AN12: 0 | AO12: 0 | AP12: 0 | AQ12: 0 | AR12: 0 | AS12: 0 | AT12: 0 | AU12: 5 | AV12: 0 | AW12: 0 | AX12: 0 | AY12: 0 | AZ12: 0 | BA12: 0 | BB12: 0 | BC12: 0 | BD12: 0 | BE12: 0 | BF12: 0 | BG12: 0 | BH12: 0 | BI12: 0 | BJ12: 0 | BK12: 0 | BM12: =IFERROR(VALUE(F12),"") -> 183.77 | BN12: =IF(R12="-","",IFERROR(VALUE(LEFT(Q12,LEN(Q12)-2)),"")) | BO12: =IF(R12="-","",IFERROR(VALUE(LEFT(R12,LEN(R12)-5)),"")) | BP12: =IF(R12="-","",IFERROR(VALUE(F12),"")) | BQ12: =IF(R12="-",1,0) -> 1
A13: JQC9414 | B13: R5155 | C13: ROTA TRANSPORTES - ITABUNA | D13: EDVALDO ELIAS SILVA - 99881624568 | E13: 46277 | F13: 38.64 | G13: 0.1306713 | H13: 0.029560185 | I13: 0 | J13: 0 | K13: 0 | L13: 0 | M13: 0 | N13: 0 | O13: 0 | P13: 0 | Q13: - | R13: - | S13: 0 | T13: 0 | U13: 0 | V13: 0 | W13: 0 | X13: 0 | Y13: 0 | Z13: 0 | AA13: 0 | AB13: 0 | AC13: BR-415 | AD13: Avenida Amélia Amado | AE13: 727226.00 | AF13: 727264.64 | AG13: 0.076319444 | AH13: 0.17378472 | AI13: 0 | AJ13: 0 | AK13: 0 | AL13: 0 | AM13: N/A | AN13: 0 | AO13: 1 | AP13: 0 | AQ13: 0 | AR13: 0 | AS13: 0 | AT13: 0 | AU13: 0 | AV13: 0 | AW13: 0 | AX13: 0 | AY13: 0 | AZ13: 0 | BA13: 0 | BB13: 0 | BC13: 0 | BD13: 0 | BE13: 0 | BF13: 0 | BG13: 0 | BH13: 0 | BI13: 0 | BJ13: 0 | BK13: 0 | BM13: =IFERROR(VALUE(F13),"") -> 38.64 | BN13: =IF(R13="-","",IFERROR(VALUE(LEFT(Q13,LEN(Q13)-2)),"")) | BO13: =IF(R13="-","",IFERROR(VALUE(LEFT(R13,LEN(R13)-5)),"")) | BP13: =IF(R13="-","",IFERROR(VALUE(F13),"")) | BQ13: =IF(R13="-",1,0) -> 1
A14: JQC9414 | B14: R5155 | C14: ROTA TRANSPORTES - ITABUNA | D14: MARCOS CARVALHO RIBEIRO - 03981643550, EDVALDO ELIAS SILVA - 99881624568, EMERSON ANDRADE DA SILVA - 96170824549 | E14: 46279 | F14: 167.71 | G14: 0.35394676 | H14: 0.15900463 | I14: 0.0017013889 | J14: 0 | K14: 1 | L14: 0 | M14: 0 | N14: 3 | O14: 0 | P14: 0 | Q14: - | R14: - | S14: 0 | T14: 0 | U14: 0 | V14: 0 | W14: 0 | X14: 0 | Y14: 0 | Z14: 0 | AA14: 0 | AB14: 0 | AC14: Rua K | AD14: Avenida Amélia Amado | AE14: 727264.64 | AF14: 727432.35 | AG14: 0.32133102 | AH14: 0.12704861 | AI14: 0 | AJ14: 0 | AK14: 0 | AL14: 0 | AM14: N/A | AN14: 0 | AO14: 2 | AP14: 0 | AQ14: 0 | AR14: 0 | AS14: 0 | AT14: 0 | AU14: 1 | AV14: 0 | AW14: 0 | AX14: 0 | AY14: 0 | AZ14: 0 | BA14: 0 | BB14: 0 | BC14: 0 | BD14: 0 | BE14: 0 | BF14: 0 | BG14: 0 | BH14: 0 | BI14: 0 | BJ14: 0 | BK14: 0 | BM14: =IFERROR(VALUE(F14),"") -> 167.71 | BN14: =IF(R14="-","",IFERROR(VALUE(LEFT(Q14,LEN(Q14)-2)),"")) | BO14: =IF(R14="-","",IFERROR(VALUE(LEFT(R14,LEN(R14)-5)),"")) | BP14: =IF(R14="-","",IFERROR(VALUE(F14),"")) | BQ14: =IF(R14="-",1,0) -> 1
A15: OUK9598 | B15: R7005 | C15: ROTA TRANSPORTES - ITABUNA | E15: 46273 | F15: 0.34 | G15: 0.0059490741 | H15: 0 | I15: 0 | J15: 0 | K15: 0 | L15: 0 | M15: 0 | N15: 0 | O15: 0 | P15: 0 | Q15: 0.13 L | R15: 2.56 Km/L | S15: 0 | T15: 0.0037037037 | U15: 0.0012731481 | V15: 0.00011574074 | W15: 0 | X15: 0 | Y15: 0 | Z15: 0 | AA15: 0 | AB15: 0 | AE15: 502189.71 | AF15: 502190.05 | AG15: 0.0041550926 | AH15: 0.01994213 | AI15: 0 | AJ15: 0 | AK15: 0 | AL15: 0 | AM15: N/A | AN15: 0 | AO15: 0 | AP15: 0 | AQ15: 0 | AR15: 0 | AS15: 0 | AT15: 0 | AU15: 0 | AV15: 0 | AW15: 0 | AX15: 0 | AY15: 0 | AZ15: 0 | BA15: 0 | BB15: 0 | BC15: 0 | BD15: 0 | BE15: 0 | BF15: 0 | BG15: 0 | BH15: 0 | BI15: 0 | BJ15: 0 | BK15: 0 | BM15: =IFERROR(VALUE(F15),"") -> 0.34 | BN15: =IF(R15="-","",IFERROR(VALUE(LEFT(Q15,LEN(Q15)-2)),"")) -> 0.13 | BO15: =IF(R15="-","",IFERROR(VALUE(LEFT(R15,LEN(R15)-5)),"")) -> 2.56 | BP15: =IF(R15="-","",IFERROR(VALUE(F15),"")) -> 0.34 | BQ15: =IF(R15="-",1,0) -> 0
A16: OUK9598 | B16: R7005 | C16: ROTA TRANSPORTES - ITABUNA | E16: 46274 | F16: 0.00 | G16: 0 | H16: 0 | I16: 0 | J16: 0 | K16: 0 | L16: 0 | M16: 0 | N16: 0 | O16: 0 | P16: 0 | Q16: - | R16: - | S16: 0 | T16: 0 | U16: 0 | V16: 0 | W16: 0 | X16: 0 | Y16: 0 | Z16: 0 | AA16: 0 | AB16: 0 | AE16: 502190.05 | AF16: 502190.05 | AG16: 0 | AH16: 0.017824074 | AI16: 0 | AJ16: 0 | AK16: 0 | AL16: 0 | AM16: N/A | AN16: 0 | AO16: 0 | AP16: 0 | AQ16: 0 | AR16: 0 | AS16: 0 | AT16: 0 | AU16: 0 | AV16: 0 | AW16: 0 | AX16: 0 | AY16: 0 | AZ16: 0 | BA16: 0 | BB16: 0 | BC16: 0 | BD16: 0 | BE16: 0 | BF16: 0 | BG16: 0 | BH16: 0 | BI16: 0 | BJ16: 0 | BK16: 0 | BM16: =IFERROR(VALUE(F16),"") -> 0 | BN16: =IF(R16="-","",IFERROR(VALUE(LEFT(Q16,LEN(Q16)-2)),"")) | BO16: =IF(R16="-","",IFERROR(VALUE(LEFT(R16,LEN(R16)-5)),"")) | BP16: =IF(R16="-","",IFERROR(VALUE(F16),"")) | BQ16: =IF(R16="-",1,0) -> 1
A17: OUK9598 | B17: R7005 | C17: ROTA TRANSPORTES - ITABUNA | D17: JOSE EUDES SANTOS - 93703503572 | E17: 46275 | F17: 175.25 | G17: 0.25594907 | H17: 0.13570602 | I17: 0.0022685185 | J17: 0 | K17: 0 | L17: 0 | M17: 0 | N17: 0 | O17: 0 | P17: 0.01818287 | Q17: 24.98 L | R17: 7.02 Km/L | S17: 0 | T17: 0.067361111 | U17: 0.031597222 | V17: 0.09537037 | W17: 0.00034722222 | X17: 0 | Y17: 0 | Z17: 0 | AA17: 0 | AB17: 0 | AE17: 502190.05 | AF17: 502365.29 | AG17: 0.15369213 | AH17: 0.19775463 | AI17: 0 | AJ17: 0 | AK17: 0 | AL17: 0 | AM17: N/A | AN17: 0 | AO17: 0 | AP17: 0 | AQ17: 0 | AR17: 0 | AS17: 0 | AT17: 0 | AU17: 0 | AV17: 0 | AW17: 0 | AX17: 0 | AY17: 0 | AZ17: 0 | BA17: 0 | BB17: 0 | BC17: 0 | BD17: 0 | BE17: 0 | BF17: 0 | BG17: 0 | BH17: 0 | BI17: 0 | BJ17: 0 | BK17: 0 | BM17: =IFERROR(VALUE(F17),"") -> 175.25 | BN17: =IF(R17="-","",IFERROR(VALUE(LEFT(Q17,LEN(Q17)-2)),"")) -> 24.98 | BO17: =IF(R17="-","",IFERROR(VALUE(LEFT(R17,LEN(R17)-5)),"")) -> 7.02 | BP17: =IF(R17="-","",IFERROR(VALUE(F17),"")) -> 175.25 | BQ17: =IF(R17="-",1,0) -> 0
A18: OUK9598 | B18: R7005 | C18: ROTA TRANSPORTES - ITABUNA | D18: JOSE EUDES SANTOS - 93703503572 | E18: 46276 | F18: 242.45 | G18: 0.30369213 | H18: 0.21016204 | I18: 0.0046412037 | J18: 0 | K18: 0 | L18: 0 | M18: 0 | N18: 0 | O18: 0 | P18: 0.030960648 | Q18: 44.94 L | R18: 5.39 Km/L | S18: 0 | T18: 0.086689815 | U18: 0.0403125 | V18: 0.14716435 | W18: 0.00071759259 | X18: 0 | Y18: 5.787037e-05 | Z18: 0 | AA18: 0 | AB18: 0 | AE18: 502365.29 | AF18: 502607.74 | AG18: 0.21251157 | AH18: 0.15988426 | AI18: 0 | AJ18: 0 | AK18: 0 | AL18: 0 | AM18: N/A | AN18: 0 | AO18: 0 | AP18: 0 | AQ18: 0 | AR18: 0 | AS18: 0 | AT18: 0 | AU18: 1 | AV18: 0 | AW18: 0 | AX18: 0 | AY18: 0 | AZ18: 0 | BA18: 0 | BB18: 0 | BC18: 0 | BD18: 0 | BE18: 0 | BF18: 0 | BG18: 0 | BH18: 0 | BI18: 0 | BJ18: 0 | BK18: 0 | BM18: =IFERROR(VALUE(F18),"") -> 242.45 | BN18: =IF(R18="-","",IFERROR(VALUE(LEFT(Q18,LEN(Q18)-2)),"")) -> 44.94 | BO18: =IF(R18="-","",IFERROR(VALUE(LEFT(R18,LEN(R18)-5)),"")) -> 5.39 | BP18: =IF(R18="-","",IFERROR(VALUE(F18),"")) -> 242.45 | BQ18: =IF(R18="-",1,0) -> 0
A19: OUK9598 | B19: R7005 | C19: ROTA TRANSPORTES - ITABUNA | E19: 46277 | F19: 0.14 | G19: 0.0030092593 | H19: 0 | I19: 0 | J19: 0 | K19: 0 | L19: 0 | M19: 0 | N19: 0 | O19: 0 | P19: 0 | Q19: 0.06 L | R19: 2.46 Km/L | S19: 0 | T19: 0.0024305556 | U19: 0.00034722222 | V19: 0 | W19: 0 | X19: 0 | Y19: 0 | Z19: 0 | AA19: 0 | AB19: 0 | AE19: 502607.74 | AF19: 502607.87 | AG19: 0.0010069444 | AH19: 0.021388889 | AI19: 0 | AJ19: 0 | AK19: 0 | AL19: 0 | AM19: N/A | AN19: 0 | AO19: 0 | AP19: 0 | AQ19: 0 | AR19: 0 | AS19: 0 | AT19: 0 | AU19: 0 | AV19: 0 | AW19: 0 | AX19: 0 | AY19: 0 | AZ19: 0 | BA19: 0 | BB19: 0 | BC19: 0 | BD19: 0 | BE19: 0 | BF19: 0 | BG19: 0 | BH19: 0 | BI19: 0 | BJ19: 0 | BK19: 0 | BM19: =IFERROR(VALUE(F19),"") -> 0.14 | BN19: =IF(R19="-","",IFERROR(VALUE(LEFT(Q19,LEN(Q19)-2)),"")) -> 0.06 | BO19: =IF(R19="-","",IFERROR(VALUE(LEFT(R19,LEN(R19)-5)),"")) -> 2.46 | BP19: =IF(R19="-","",IFERROR(VALUE(F19),"")) -> 0.14 | BQ19: =IF(R19="-",1,0) -> 0
A20: OUK9598 | B20: R7005 | C20: ROTA TRANSPORTES - ITABUNA | D20: ROBERTO CARLOS HIGINO P JUNIOR - 09578097514 | E20: 46279 | F20: 90.26 | G20: 0.13196759 | H20: 0.12896991 | I20: 0.00024305556 | J20: 0 | K20: 0 | L20: 0 | M20: 0 | N20: 0 | O20: 0 | P20: 0 | Q20: 15.81 L | R20: 5.71 Km/L | S20: 0.00011574074 | T20: 0.047569444 | U20: 0.036458333 | V20: 0.045949074 | W20: 0 | X20: 0 | Y20: 0 | Z20: 0 | AA20: 0 | AB20: 0 | AE20: 502607.87 | AF20: 502698.13 | AG20: 0.10657407 | AH20: 0.064826389 | AI20: 0 | AJ20: 0 | AK20: 0 | AL20: 0 | AM20: N/A | AN20: 0 | AO20: 0 | AP20: 0 | AQ20: 0 | AR20: 0 | AS20: 0 | AT20: 0 | AU20: 1 | AV20: 0 | AW20: 0 | AX20: 0 | AY20: 0 | AZ20: 0 | BA20: 0 | BB20: 0 | BC20: 0 | BD20: 0 | BE20: 0 | BF20: 0 | BG20: 0 | BH20: 0 | BI20: 0 | BJ20: 0 | BK20: 0 | BM20: =IFERROR(VALUE(F20),"") -> 90.26 | BN20: =IF(R20="-","",IFERROR(VALUE(LEFT(Q20,LEN(Q20)-2)),"")) -> 15.81 | BO20: =IF(R20="-","",IFERROR(VALUE(LEFT(R20,LEN(R20)-5)),"")) -> 5.71 | BP20: =IF(R20="-","",IFERROR(VALUE(F20),"")) -> 90.26 | BQ20: =IF(R20="-",1,0) -> 0
A21: OUK7589 | B21: R7015 | C21: ROTA TRANSPORTES - ITABUNA | D21: ANTONIEL SILVA NOVAIS - 16687097830 | E21: 46273 | F21: 324.04 | G21: 0.32373843 | H21: 0.32052083 | I21: 0.00024305556 | J21: 0 | K21: 1 | L21: 0 | M21: 0 | N21: 1 | O21: 0 | P21: 0.0084722222 | Q21: 57.56 L | R21: 5.63 Km/L | S21: 0 | T21: 0.078472222 | U21: 0.07025463 | V21: 0.1699537 | W21: 0.00018518519 | X21: 0 | Y21: 0 | Z21: 0 | AA21: 0 | AB21: 0 | AC21: Rua Xavantes | AD21: Rua Xavantes | AE21: 511386.19 | AF21: 511710.23 | AG21: 0.28899306 | AH21: 0.072835648 | AI21: 0 | AJ21: 0 | AK21: 0 | AL21: 0 | AM21: N/A | AN21: 0 | AO21: 0 | AP21: 0 | AQ21: 0 | AR21: 0 | AS21: 0 | AT21: 0 | AU21: 0 | AV21: 0 | AW21: 0 | AX21: 0 | AY21: 0 | AZ21: 0 | BA21: 0 | BB21: 0 | BC21: 0 | BD21: 0 | BE21: 0 | BF21: 0 | BG21: 0 | BH21: 0 | BI21: 0 | BJ21: 0 | BK21: 0 | BM21: =IFERROR(VALUE(F21),"") -> 324.04 | BN21: =IF(R21="-","",IFERROR(VALUE(LEFT(Q21,LEN(Q21)-2)),"")) -> 57.56 | BO21: =IF(R21="-","",IFERROR(VALUE(LEFT(R21,LEN(R21)-5)),"")) -> 5.63 | BP21: =IF(R21="-","",IFERROR(VALUE(F21),"")) -> 324.04 | BQ21: =IF(R21="-",1,0) -> 0
A22: OUK7589 | B22: R7015 | C22: ROTA TRANSPORTES - ITABUNA | E22: 46274 | F22: 1.75 | G22: 0.023900463 | H22: 0 | I22: 0 | J22: 0 | K22: 0 | L22: 0 | M22: 0 | N22: 0 | O22: 0 | P22: 0.014502315 | Q22: 1.65 L | R22: 1.06 Km/L | S22: 0 | T22: 0.02025463 | U22: 0.0023148148 | V22: 0.0005787037 | W22: 0 | X22: 0 | Y22: 0 | Z22: 0 | AA22: 0 | AB22: 0 | AC22: Rua Tupinambás | AD22: Avenida Presidente Dutra | AE22: 511710.23 | AF22: 511711.98 | AG22: 0.0059953704 | AH22: 0.022222222 | AI22: 0 | AJ22: 0 | AK22: 0 | AL22: 0 | AM22: N/A | AN22: 0 | AO22: 0 | AP22: 0 | AQ22: 0 | AR22: 0 | AS22: 0 | AT22: 0 | AU22: 0 | AV22: 0 | AW22: 0 | AX22: 0 | AY22: 0 | AZ22: 0 | BA22: 0 | BB22: 0 | BC22: 0 | BD22: 0 | BE22: 0 | BF22: 0 | BG22: 0 | BH22: 0 | BI22: 0 | BJ22: 0 | BK22: 0 | BM22: =IFERROR(VALUE(F22),"") -> 1.75 | BN22: =IF(R22="-","",IFERROR(VALUE(LEFT(Q22,LEN(Q22)-2)),"")) -> 1.65 | BO22: =IF(R22="-","",IFERROR(VALUE(LEFT(R22,LEN(R22)-5)),"")) -> 1.06 | BP22: =IF(R22="-","",IFERROR(VALUE(F22),"")) -> 1.75 | BQ22: =IF(R22="-",1,0) -> 0
A23: OUK7589 | B23: R7015 | C23: ROTA TRANSPORTES - ITABUNA | D23: JAIMILTON OLIVEIRA ROCHA - 05812579520 | E23: 46275 | F23: 109.12 | G23: 0.20525463 | H23: 0.0171875 | I23: 0.00065972222 | J23: 0 | K23: 0 | L23: 0 | M23: 0 | N23: 0 | O23: 0 | P23: 0.027962963 | Q23: 22.26 L | R23: 4.90 Km/L | S23: 0 | T23: 0.084490741 | U23: 0.082060185 | V23: 0.030439815 | W23: 0.00011574074 | X23: 0 | Y23: 0 | Z23: 0 | AA23: 0 | AB23: 0 | AC23: Avenida Presidente Dutra | AD23: Avenida Presidente Dutra | AE23: 511711.98 | AF23: 511821.10 | AG23: 0.15728009 | AH23: 0.14041667 | AI23: 0 | AJ23: 0 | AK23: 0 | AL23: 0 | AM23: N/A | AN23: 0 | AO23: 0 | AP23: 0 | AQ23: 0 | AR23: 0 | AS23: 0 | AT23: 0 | AU23: 0 | AV23: 0 | AW23: 0 | AX23: 0 | AY23: 0 | AZ23: 0 | BA23: 0 | BB23: 0 | BC23: 0 | BD23: 0 | BE23: 0 | BF23: 0 | BG23: 0 | BH23: 0 | BI23: 0 | BJ23: 0 | BK23: 0 | BM23: =IFERROR(VALUE(F23),"") -> 109.12 | BN23: =IF(R23="-","",IFERROR(VALUE(LEFT(Q23,LEN(Q23)-2)),"")) -> 22.26 | BO23: =IF(R23="-","",IFERROR(VALUE(LEFT(R23,LEN(R23)-5)),"")) -> 4.9 | BP23: =IF(R23="-","",IFERROR(VALUE(F23),"")) -> 109.12 | BQ23: =IF(R23="-",1,0) -> 0
A24: OUK7589 | B24: R7015 | C24: ROTA TRANSPORTES - ITABUNA | E24: 46276 | F24: 107.82 | G24: 0.19203704 | H24: 0 | I24: 0.00038194444 | J24: 0 | K24: 0 | L24: 0 | M24: 0 | N24: 1 | O24: 0 | P24: 0.023229167 | Q24: 21.04 L | R24: 5.12 Km/L | S24: 0 | T24: 0.071180556 | U24: 0.084259259 | V24: 0.030439815 | W24: 0 | X24: 0 | Y24: 0 | Z24: 0 | AA24: 0 | AB24: 0 | AC24: Avenida Presidente Dutra | AD24: Avenida Presidente Dutra | AE24: 511821.10 | AF24: 511928.92 | AG24: 0.15143519 | AH24: 0.1316088 | AI24: 0 | AJ24: 0 | AK24: 0 | AL24: 0 | AM24: N/A | AN24: 0 | AO24: 0 | AP24: 0 | AQ24: 0 | AR24: 0 | AS24: 0 | AT24: 0 | AU24: 0 | AV24: 0 | AW24: 0 | AX24: 0 | AY24: 0 | AZ24: 0 | BA24: 0 | BB24: 0 | BC24: 0 | BD24: 0 | BE24: 0 | BF24: 0 | BG24: 0 | BH24: 0 | BI24: 0 | BJ24: 0 | BK24: 0 | BM24: =IFERROR(VALUE(F24),"") -> 107.82 | BN24: =IF(R24="-","",IFERROR(VALUE(LEFT(Q24,LEN(Q24)-2)),"")) -> 21.04 | BO24: =IF(R24="-","",IFERROR(VALUE(LEFT(R24,LEN(R24)-5)),"")) -> 5.12 | BP24: =IF(R24="-","",IFERROR(VALUE(F24),"")) -> 107.82 | BQ24: =IF(R24="-",1,0) -> 0
A25: OUK7589 | B25: R7015 | C25: ROTA TRANSPORTES - ITABUNA | E25: 46277 | F25: 0.14 | G25: 0.004224537 | H25: 0 | I25: 5.787037e-05 | J25: 0 | K25: 0 | L25: 0 | M25: 0 | N25: 0 | O25: 0 | P25: 0 | Q25: 0.25 L | R25: 0.55 Km/L | S25: 0 | T25: 0.0028935185 | U25: 0.00081018519 | V25: 0.00023148148 | W25: 0 | X25: 0 | Y25: 0 | Z25: 0 | AA25: 0 | AB25: 0 | AC25: Avenida Presidente Dutra | AD25: Avenida Presidente Dutra | AE25: 511928.92 | AF25: 511929.06 | AG25: 0.0011805556 | AH25: 0.030185185 | AI25: 0 | AJ25: 0 | AK25: 0 | AL25: 0 | AM25: N/A | AN25: 0 | AO25: 0 | AP25: 0 | AQ25: 0 | AR25: 0 | AS25: 0 | AT25: 0 | AU25: 0 | AV25: 0 | AW25: 0 | AX25: 0 | AY25: 0 | AZ25: 0 | BA25: 0 | BB25: 0 | BC25: 0 | BD25: 0 | BE25: 0 | BF25: 0 | BG25: 0 | BH25: 0 | BI25: 0 | BJ25: 0 | BK25: 0 | BM25: =IFERROR(VALUE(F25),"") -> 0.14 | BN25: =IF(R25="-","",IFERROR(VALUE(LEFT(Q25,LEN(Q25)-2)),"")) -> 0.25 | BO25: =IF(R25="-","",IFERROR(VALUE(LEFT(R25,LEN(R25)-5)),"")) -> 0.55 | BP25: =IF(R25="-","",IFERROR(VALUE(F25),"")) -> 0.14 | BQ25: =IF(R25="-",1,0) -> 0
A26: OUK7589 | B26: R7015 | C26: ROTA TRANSPORTES - ITABUNA | D26: VALDINEUDO JOSE ALVES CLARO - 87261758434 | E26: 46279 | F26: 107.89 | G26: 0.19121528 | H26: 0.0036111111 | I26: 0.00052083333 | J26: 0 | K26: 0 | L26: 0 | M26: 0 | N26: 1 | O26: 0 | P26: 0.027789352 | Q26: 21.97 L | R26: 4.91 Km/L | S26: 0 | T26: 0.071643519 | U26: 0.076747685 | V26: 0.03587963 | W26: 0.00037037037 | X26: 0 | Y26: 6.9444444e-05 | Z26: 0 | AA26: 0 | AB26: 0 | AC26: Avenida Presidente Dutra | AD26: Avenida Presidente Dutra | AE26: 511929.06 | AF26: 512036.95 | AG26: 0.14619213 | AH26: 0.12109954 | AI26: 0 | AJ26: 0 | AK26: 0 | AL26: 0 | AM26: N/A | AN26: 0 | AO26: 0 | AP26: 0 | AQ26: 0 | AR26: 0 | AS26: 0 | AT26: 0 | AU26: 0 | AV26: 0 | AW26: 0 | AX26: 0 | AY26: 0 | AZ26: 0 | BA26: 0 | BB26: 0 | BC26: 0 | BD26: 0 | BE26: 0 | BF26: 0 | BG26: 0 | BH26: 0 | BI26: 0 | BJ26: 0 | BK26: 0 | BM26: =IFERROR(VALUE(F26),"") -> 107.89 | BN26: =IF(R26="-","",IFERROR(VALUE(LEFT(Q26,LEN(Q26)-2)),"")) -> 21.97 | BO26: =IF(R26="-","",IFERROR(VALUE(LEFT(R26,LEN(R26)-5)),"")) -> 4.91 | BP26: =IF(R26="-","",IFERROR(VALUE(F26),"")) -> 107.89 | BQ26: =IF(R26="-",1,0) -> 0
A27: OUK7974 | B27: R7025 | C27: ROTA TRANSPORTES - ITABUNA | E27: 46273 | F27: 175.73 | G27: 0.17023148 | H27: 0 | I27: 0.00013888889 | J27: 0 | K27: 1 | L27: 0 | M27: 0 | N27: 2 | O27: 0 | P27: 0 | Q27: 33.79 L | R27: 5.20 Km/L | S27: 0 | T27: 0.038425926 | U27: 0.035763889 | V27: 0.093055556 | W27: 0 | X27: 0 | Y27: 0 | Z27: 0 | AA27: 0 | AB27: 0 | AC27: Rua Castro Alves | AD27: Rua Bela Vista | AE27: 615405.81 | AF27: 615581.54 | AG27: 0.15524306 | AH27: 0.036840278 | AI27: 0 | AJ27: 0 | AK27: 0 | AL27: 0 | AM27: N/A | AN27: 0 | AO27: 0 | AP27: 0 | AQ27: 0 | AR27: 0 | AS27: 0 | AT27: 0 | AU27: 1 | AV27: 0 | AW27: 0 | AX27: 0 | AY27: 0 | AZ27: 0 | BA27: 0 | BB27: 0 | BC27: 0 | BD27: 0 | BE27: 0 | BF27: 0 | BG27: 0 | BH27: 0 | BI27: 0 | BJ27: 0 | BK27: 0 | BM27: =IFERROR(VALUE(F27),"") -> 175.73 | BN27: =IF(R27="-","",IFERROR(VALUE(LEFT(Q27,LEN(Q27)-2)),"")) -> 33.79 | BO27: =IF(R27="-","",IFERROR(VALUE(LEFT(R27,LEN(R27)-5)),"")) -> 5.2 | BP27: =IF(R27="-","",IFERROR(VALUE(F27),"")) -> 175.73 | BQ27: =IF(R27="-",1,0) -> 0
A28: OUK7974 | B28: R7025 | C28: ROTA TRANSPORTES - ITABUNA | E28: 46274 | F28: 296.22 | G28: 0.23802083 | H28: 0 | I28: 0.00011574074 | J28: 0 | K28: 2 | L28: 0 | M28: 0 | N28: 1 | O28: 0 | P28: 0 | Q28: 50.70 L | R28: 5.84 Km/L | S28: 0 | T28: 0.044212963 | U28: 0.026851852 | V28: 0.15810185 | W28: 0.00011574074 | X28: 0 | Y28: 0 | Z28: 0 | AA28: 0 | AB28: 0 | AC28: Rua Rui Barbosa | AD28: Rua Bela Vista | AE28: 615581.54 | AF28: 615877.76 | AG28: 0.21241898 | AH28: 0.1184375 | AI28: 0 | AJ28: 0 | AK28: 0 | AL28: 0 | AM28: N/A | AN28: 0 | AO28: 0 | AP28: 0 | AQ28: 0 | AR28: 0 | AS28: 0 | AT28: 0 | AU28: 1 | AV28: 0 | AW28: 0 | AX28: 0 | AY28: 0 | AZ28: 0 | BA28: 0 | BB28: 0 | BC28: 0 | BD28: 0 | BE28: 0 | BF28: 0 | BG28: 0 | BH28: 0 | BI28: 0 | BJ28: 0 | BK28: 0 | BM28: =IFERROR(VALUE(F28),"") -> 296.22 | BN28: =IF(R28="-","",IFERROR(VALUE(LEFT(Q28,LEN(Q28)-2)),"")) -> 50.7 | BO28: =IF(R28="-","",IFERROR(VALUE(LEFT(R28,LEN(R28)-5)),"")) -> 5.84 | BP28: =IF(R28="-","",IFERROR(VALUE(F28),"")) -> 296.22 | BQ28: =IF(R28="-",1,0) -> 0
A29: OUK7974 | B29: R7025 | C29: ROTA TRANSPORTES - ITABUNA | D29: FABIANO REIS DOS SANTOS - 06063406530 | E29: 46275 | F29: 297.74 | G29: 0.25791667 | H29: 0.0056365741 | I29: 0.00024305556 | J29: 0 | K29: 0 | L29: 0 | M29: 0 | N29: 1 | O29: 0 | P29: 0 | Q29: 52.49 L | R29: 5.67 Km/L | S29: 0 | T29: 0.061574074 | U29: 0.029282407 | V29: 0.15856481 | W29: 0.00034722222 | X29: 0 | Y29: 0 | Z29: 0 | AA29: 0 | AB29: 0 | AC29: Rua Rui Barbosa | AD29: Rua Bela Vista | AE29: 615877.76 | AF29: 616175.49 | AG29: 0.22024306 | AH29: 0.096446759 | AI29: 0 | AJ29: 0 | AK29: 0 | AL29: 0 | AM29: N/A | AN29: 0 | AO29: 0 | AP29: 0 | AQ29: 0 | AR29: 0 | AS29: 0 | AT29: 0 | AU29: 0 | AV29: 0 | AW29: 0 | AX29: 0 | AY29: 0 | AZ29: 0 | BA29: 0 | BB29: 0 | BC29: 0 | BD29: 0 | BE29: 0 | BF29: 0 | BG29: 0 | BH29: 0 | BI29: 0 | BJ29: 0 | BK29: 0 | BM29: =IFERROR(VALUE(F29),"") -> 297.74 | BN29: =IF(R29="-","",IFERROR(VALUE(LEFT(Q29,LEN(Q29)-2)),"")) -> 52.49 | BO29: =IF(R29="-","",IFERROR(VALUE(LEFT(R29,LEN(R29)-5)),"")) -> 5.67 | BP29: =IF(R29="-","",IFERROR(VALUE(F29),"")) -> 297.74 | BQ29: =IF(R29="-",1,0) -> 0
A30: OUK7974 | B30: R7025 | C30: ROTA TRANSPORTES - ITABUNA | E30: 46276 | F30: 297.71 | G30: 0.25681713 | H30: 0 | I30: 0.00023148148 | J30: 0 | K30: 0 | L30: 0 | M30: 0 | N30: 4 | O30: 0 | P30: 0 | Q30: 52.18 L | R30: 5.71 Km/L | S30: 0 | T30: 0.055208333 | U30: 0.038657407 | V30: 0.15601852 | W30: 0.00023148148 | X30: 0 | Y30: 0 | Z30: 0 | AA30: 0 | AB30: 0 | AC30: Rua Bela Vista | AD30: Rua Bela Vista | AE30: 616175.49 | AF30: 616473.20 | AG30: 0.23126157 | AH30: 0.10664352 | AI30: 0 | AJ30: 0 | AK30: 0 | AL30: 0 | AM30: N/A | AN30: 0 | AO30: 0 | AP30: 0 | AQ30: 0 | AR30: 0 | AS30: 0 | AT30: 0 | AU30: 0 | AV30: 0 | AW30: 0 | AX30: 0 | AY30: 0 | AZ30: 0 | BA30: 0 | BB30: 0 | BC30: 0 | BD30: 0 | BE30: 0 | BF30: 0 | BG30: 0 | BH30: 0 | BI30: 0 | BJ30: 0 | BK30: 0 | BM30: =IFERROR(VALUE(F30),"") -> 297.71 | BN30: =IF(R30="-","",IFERROR(VALUE(LEFT(Q30,LEN(Q30)-2)),"")) -> 52.18 | BO30: =IF(R30="-","",IFERROR(VALUE(LEFT(R30,LEN(R30)-5)),"")) -> 5.71 | BP30: =IF(R30="-","",IFERROR(VALUE(F30),"")) -> 297.71 | BQ30: =IF(R30="-",1,0) -> 0
A31: OUK7974 | B31: R7025 | C31: ROTA TRANSPORTES - ITABUNA | E31: 46279 | F31: 297.83 | G31: 0.25217593 | H31: 0 | I31: 0.00037037037 | J31: 0 | K31: 0 | L31: 0 | M31: 0 | N31: 2 | O31: 0 | P31: 0 | Q31: 53.17 L | R31: 5.60 Km/L | S31: 0 | T31: 0.058680556 | U31: 0.029166667 | V31: 0.15601852 | W31: 0.00023148148 | X31: 0 | Y31: 0 | Z31: 0 | AA31: 0 | AB31: 0 | AC31: Rua Bela Vista | AD31: Rua Bela Vista | AE31: 616473.20 | AF31: 616771.03 | AG31: 0.22146991 | AH31: 0.099884259 | AI31: 0 | AJ31: 0 | AK31: 0 | AL31: 0 | AM31: N/A | AN31: 0 | AO31: 0 | AP31: 0 | AQ31: 0 | AR31: 0 | AS31: 0 | AT31: 0 | AU31: 2 | AV31: 0 | AW31: 0 | AX31: 0 | AY31: 0 | AZ31: 0 | BA31: 0 | BB31: 0 | BC31: 0 | BD31: 0 | BE31: 0 | BF31: 0 | BG31: 0 | BH31: 0 | BI31: 0 | BJ31: 0 | BK31: 0 | BM31: =IFERROR(VALUE(F31),"") -> 297.83 | BN31: =IF(R31="-","",IFERROR(VALUE(LEFT(Q31,LEN(Q31)-2)),"")) -> 53.17 | BO31: =IF(R31="-","",IFERROR(VALUE(LEFT(R31,LEN(R31)-5)),"")) -> 5.6 | BP31: =IF(R31="-","",IFERROR(VALUE(F31),"")) -> 297.83 | BQ31: =IF(R31="-",1,0) -> 0
A32: OUK3365 | B32: R7035 | C32: ROTA TRANSPORTES - ITABUNA | E32: 46274 | F32: 0.23 | G32: 0.0025694444 | H32: 0 | I32: 0 | J32: 0 | K32: 0 | L32: 0 | M32: 0 | N32: 0 | O32: 0 | P32: 0 | Q32: 0.17 L | R32: 1.35 Km/L | S32: 0 | T32: 0.0015046296 | U32: 0.00034722222 | V32: 0.00034722222 | W32: 0.00011574074 | X32: 0 | Y32: 0 | Z32: 0 | AA32: 0 | AB32: 0 | AC32: Avenida Governador Roberto Santos | AD32: Avenida Governador Roberto Santos | AE32: 572437.20 | AF32: 572437.42 | AG32: 0.0011574074 | AH32: 0.0033796296 | AI32: 0 | AJ32: 0 | AK32: 0 | AL32: 0 | AM32: N/A | AN32: 0 | AO32: 0 | AP32: 0 | AQ32: 0 | AR32: 0 | AS32: 0 | AT32: 0 | AU32: 0 | AV32: 0 | AW32: 0 | AX32: 0 | AY32: 0 | AZ32: 0 | BA32: 0 | BB32: 0 | BC32: 0 | BD32: 0 | BE32: 0 | BF32: 0 | BG32: 0 | BH32: 0 | BI32: 0 | BJ32: 0 | BK32: 0 | BM32: =IFERROR(VALUE(F32),"") -> 0.23 | BN32: =IF(R32="-","",IFERROR(VALUE(LEFT(Q32,LEN(Q32)-2)),"")) -> 0.17 | BO32: =IF(R32="-","",IFERROR(VALUE(LEFT(R32,LEN(R32)-5)),"")) -> 1.35 | BP32: =IF(R32="-","",IFERROR(VALUE(F32),"")) -> 0.23 | BQ32: =IF(R32="-",1,0) -> 0
A33: OUK3365 | B33: R7035 | C33: ROTA TRANSPORTES - ITABUNA | D33: EDSON RIBEIRO BATISTA SANTOS - 03640303563 | E33: 46276 | F33: 6.34 | G33: 0.01412037 | H33: 0.01412037 | I33: 0.00010416667 | J33: 0 | K33: 0 | L33: 0 | M33: 0 | N33: 0 | O33: 0 | P33: 0 | Q33: 1.57 L | R33: 4.04 Km/L | S33: 0 | T33: 0.0046296296 | U33: 0.0060185185 | V33: 0.0032407407 | W33: 0 | X33: 0 | Y33: 0 | Z33: 0 | AA33: 0 | AB33: 0 | AC33: Avenida Governador Roberto Santos | AD33: Avenida Governador Roberto Santos | AE33: 572437.42 | AF33: 572443.76 | AG33: 0.012893519 | AH33: 0.015428241 | AI33: 0 | AJ33: 0 | AK33: 0 | AL33: 0 | AM33: N/A | AN33: 0 | AO33: 0 | AP33: 0 | AQ33: 0 | AR33: 0 | AS33: 0 | AT33: 0 | AU33: 0 | AV33: 0 | AW33: 0 | AX33: 0 | AY33: 0 | AZ33: 0 | BA33: 0 | BB33: 0 | BC33: 0 | BD33: 0 | BE33: 0 | BF33: 0 | BG33: 0 | BH33: 0 | BI33: 0 | BJ33: 0 | BK33: 0 | BM33: =IFERROR(VALUE(F33),"") -> 6.34 | BN33: =IF(R33="-","",IFERROR(VALUE(LEFT(Q33,LEN(Q33)-2)),"")) -> 1.57 | BO33: =IF(R33="-","",IFERROR(VALUE(LEFT(R33,LEN(R33)-5)),"")) -> 4.04 | BP33: =IF(R33="-","",IFERROR(VALUE(F33),"")) -> 6.34 | BQ33: =IF(R33="-",1,0) -> 0
A34: OUK3365 | B34: R7035 | C34: ROTA TRANSPORTES - ITABUNA | E34: 46277 | F34: 0.19 | G34: 0.0028125 | H34: 0 | I34: 0 | J34: 0 | K34: 0 | L34: 0 | M34: 0 | N34: 0 | O34: 0 | P34: 0 | Q34: 0.20 L | R34: 0.93 Km/L | S34: 0 | T34: 0.0011574074 | U34: 0.00092592593 | V34: 0.00046296296 | W34: 0 | X34: 0 | Y34: 0 | Z34: 0 | AA34: 0 | AB34: 0 | AC34: Avenida Governador Roberto Santos | AD34: Avenida Governador Roberto Santos | AE34: 572443.76 | AF34: 572443.95 | AG34: 0.0020601852 | AH34: 0.014618056 | AI34: 0 | AJ34: 0 | AK34: 0 | AL34: 0 | AM34: N/A | AN34: 0 | AO34: 0 | AP34: 0 | AQ34: 0 | AR34: 0 | AS34: 0 | AT34: 0 | AU34: 0 | AV34: 0 | AW34: 0 | AX34: 0 | AY34: 0 | AZ34: 0 | BA34: 0 | BB34: 0 | BC34: 0 | BD34: 0 | BE34: 0 | BF34: 0 | BG34: 0 | BH34: 0 | BI34: 0 | BJ34: 0 | BK34: 0 | BM34: =IFERROR(VALUE(F34),"") -> 0.19 | BN34: =IF(R34="-","",IFERROR(VALUE(LEFT(Q34,LEN(Q34)-2)),"")) -> 0.2 | BO34: =IF(R34="-","",IFERROR(VALUE(LEFT(R34,LEN(R34)-5)),"")) -> 0.93 | BP34: =IF(R34="-","",IFERROR(VALUE(F34),"")) -> 0.19 | BQ34: =IF(R34="-",1,0) -> 0
A35: JQI1373 | B35: R5485 | C35: ROTA TRANSPORTES - ITABUNA | D35: Jose Raimundo dos Santos - 00335224563, JOVANDO SANTANA MOREIRA - 65889843591, TIAGO SILVA BASTOS - 02581506539 | E35: 46273 | F35: 340.86 | G35: 0.59043981 | H35: 0.58486111 | I35: 0.00077546296 | J35: 1 | K35: 4 | L35: 0 | M35: 0 | N35: 8 | O35: 0 | P35: 0 | Q35: - | R35: - | S35: 0 | T35: 0 | U35: 0 | V35: 0 | W35: 0 | X35: 0 | Y35: 0 | Z35: 0 | AA35: 0 | AB35: 0 | AC35: Avenida Amélia Amado | AD35: Avenida Amélia Amado | AE35: 89788.48 | AF35: 90129.34 | AG35: 0.50140046 | AH35: 0.18913194 | AI35: 1.1574074e-05 | AJ35: 0 | AK35: 0 | AL35: 0 | AM35: N/A | AN35: 0 | AO35: 1 | AP35: 0 | AQ35: 0 | AR35: 0 | AS35: 0 | AT35: 0 | AU35: 3 | AV35: 0 | AW35: 0 | AX35: 0 | AY35: 0 | AZ35: 0 | BA35: 0 | BB35: 0 | BC35: 0 | BD35: 0 | BE35: 0 | BF35: 0 | BG35: 0 | BH35: 0 | BI35: 0 | BJ35: 0 | BK35: 0 | BM35: =IFERROR(VALUE(F35),"") -> 340.86 | BN35: =IF(R35="-","",IFERROR(VALUE(LEFT(Q35,LEN(Q35)-2)),"")) | BO35: =IF(R35="-","",IFERROR(VALUE(LEFT(R35,LEN(R35)-5)),"")) | BP35: =IF(R35="-","",IFERROR(VALUE(F35),"")) | BQ35: =IF(R35="-",1,0) -> 1
A36: JQI1373 | B36: R5485 | C36: ROTA TRANSPORTES - ITABUNA | D36: FABIANO REIS DOS SANTOS - 06063406530, FERNANDO DAMASCENO DE JESUS - 03779273500 | E36: 46274 | F36: 31.50 | G36: 0.084386574 | H36: 0.078402778 | I36: 4.6296296e-05 | J36: 0 | K36: 0 | L36: 0 | M36: 0 | N36: 0 | O36: 0 | P36: 0 | Q36: - | R36: - | S36: 0 | T36: 0 | U36: 0 | V36: 0 | W36: 0 | X36: 0 | Y36: 0 | Z36: 0 | AA36: 0 | AB36: 0 | AC36: Avenida Amélia Amado | AD36: Rua João Franco | AE36: 90129.34 | AF36: 90160.84 | AG36: 0.057893519 | AH36: 0.046770833 | AI36: 0 | AJ36: 0 | AK36: 0 | AL36: 0 | AM36: N/A | AN36: 0 | AO36: 0 | AP36: 0 | AQ36: 0 | AR36: 0 | AS36: 0 | AT36: 0 | AU36: 3 | AV36: 0 | AW36: 0 | AX36: 0 | AY36: 0 | AZ36: 0 | BA36: 0 | BB36: 0 | BC36: 0 | BD36: 0 | BE36: 0 | BF36: 0 | BG36: 0 | BH36: 0 | BI36: 0 | BJ36: 0 | BK36: 0 | BM36: =IFERROR(VALUE(F36),"") -> 31.5 | BN36: =IF(R36="-","",IFERROR(VALUE(LEFT(Q36,LEN(Q36)-2)),"")) | BO36: =IF(R36="-","",IFERROR(VALUE(LEFT(R36,LEN(R36)-5)),"")) | BP36: =IF(R36="-","",IFERROR(VALUE(F36),"")) | BQ36: =IF(R36="-",1,0) -> 1
A37: JQI1373 | B37: R5485 | C37: ROTA TRANSPORTES - ITABUNA | D37: Jose Adilson Dos Santos Reis - 02053767545, JUCIMAR DE JESUS SANTOS - 03136869559 | E37: 46275 | F37: 181.93 | G37: 0.42074074 | H37: 0.37482639 | I37: 0.0003125 | J37: 0 | K37: 0 | L37: 0 | M37: 0 | N37: 0 | O37: 0 | P37: 0 | Q37: - | R37: - | S37: 0 | T37: 0 | U37: 0 | V37: 0 | W37: 0 | X37: 0 | Y37: 0 | Z37: 0 | AA37: 0 | AB37: 0 | AC37: Rua Castro Alves | AD37: Rua K | AE37: 90160.84 | AF37: 90342.77 | AG37: 0.31783565 | AH37: 0.19135417 | AI37: 0 | AJ37: 0 | AK37: 0 | AL37: 0 | AM37: N/A | AN37: 0 | AO37: 0 | AP37: 0 | AQ37: 0 | AR37: 0 | AS37: 0 | AT37: 0 | AU37: 7 | AV37: 0 | AW37: 0 | AX37: 0 | AY37: 0 | AZ37: 0 | BA37: 0 | BB37: 0 | BC37: 0 | BD37: 0 | BE37: 0 | BF37: 0 | BG37: 0 | BH37: 0 | BI37: 0 | BJ37: 0 | BK37: 0 | BM37: =IFERROR(VALUE(F37),"") -> 181.93 | BN37: =IF(R37="-","",IFERROR(VALUE(LEFT(Q37,LEN(Q37)-2)),"")) | BO37: =IF(R37="-","",IFERROR(VALUE(LEFT(R37,LEN(R37)-5)),"")) | BP37: =IF(R37="-","",IFERROR(VALUE(F37),"")) | BQ37: =IF(R37="-",1,0) -> 1
A38: JQI1373 | B38: R5485 | C38: ROTA TRANSPORTES - ITABUNA | D38: JOVANDO SANTANA MOREIRA - 65889843591, ERICO OLIVEIRA PEREIRA - 04284740555, MARCELO BATISTA SANTOS - 08636731550 | E38: 46276 | F38: 167.34 | G38: 0.31263889 | H38: 0.29927083 | I38: 0.00090277778 | J38: 0 | K38: 1 | L38: 0 | M38: 0 | N38: 4 | O38: 0 | P38: 0 | Q38: - | R38: - | S38: 0 | T38: 0 | U38: 0 | V38: 0 | W38: 0 | X38: 0 | Y38: 0 | Z38: 0 | AA38: 0 | AB38: 0 | AC38: Rua João Franco | AD38: Rua K | AE38: 90342.77 | AF38: 90510.10 | AG38: 0.2565625 | AH38: 0.14783565 | AI38: 0 | AJ38: 0 | AK38: 0 | AL38: 0 | AM38: N/A | AN38: 0 | AO38: 0 | AP38: 0 | AQ38: 0 | AR38: 0 | AS38: 0 | AT38: 0 | AU38: 3 | AV38: 0 | AW38: 0 | AX38: 0 | AY38: 0 | AZ38: 0 | BA38: 0 | BB38: 0 | BC38: 0 | BD38: 0 | BE38: 0 | BF38: 0 | BG38: 0 | BH38: 0 | BI38: 0 | BJ38: 0 | BK38: 0 | BM38: =IFERROR(VALUE(F38),"") -> 167.34 | BN38: =IF(R38="-","",IFERROR(VALUE(LEFT(Q38,LEN(Q38)-2)),"")) | BO38: =IF(R38="-","",IFERROR(VALUE(LEFT(R38,LEN(R38)-5)),"")) | BP38: =IF(R38="-","",IFERROR(VALUE(F38),"")) | BQ38: =IF(R38="-",1,0) -> 1
A39: JQI1373 | B39: R5485 | C39: ROTA TRANSPORTES - ITABUNA | D39: RAFAEL DE JESUS BARRETO - 85830111500, Jose Raimundo dos Santos - 00335224563, JUCIMAR DE JESUS SANTOS - 03136869559, OSNILDO CLEMENTINO ROCHA DOS - 87948125515, TALES ANTONIO ALMEIDA ALVES JUNIOR - 09534524506 | E39: 46279 | F39: 265.67 | G39: 0.50819444 | H39: 0.45653935 | I39: 0.0019907407 | J39: 0 | K39: 1 | L39: 0 | M39: 0 | N39: 1 | O39: 0 | P39: 0 | Q39: - | R39: - | S39: 0 | T39: 0 | U39: 0 | V39: 0 | W39: 0 | X39: 0 | Y39: 0 | Z39: 0 | AA39: 0 | AB39: 0 | AC39: Avenida Amélia Amado | AD39: Rua K | AE39: 90510.10 | AF39: 90775.77 | AG39: 0.33578704 | AH39: 0.25248843 | AI39: 0 | AJ39: 0 | AK39: 0 | AL39: 0 | AM39: N/A | AN39: 0 | AO39: 0 | AP39: 0 | AQ39: 0 | AR39: 0 | AS39: 0 | AT39: 0 | AU39: 9 | AV39: 0 | AW39: 0 | AX39: 0 | AY39: 0 | AZ39: 0 | BA39: 0 | BB39: 0 | BC39: 0 | BD39: 0 | BE39: 0 | BF39: 0 | BG39: 0 | BH39: 0 | BI39: 0 | BJ39: 0 | BK39: 0 | BM39: =IFERROR(VALUE(F39),"") -> 265.67 | BN39: =IF(R39="-","",IFERROR(VALUE(LEFT(Q39,LEN(Q39)-2)),"")) | BO39: =IF(R39="-","",IFERROR(VALUE(LEFT(R39,LEN(R39)-5)),"")) | BP39: =IF(R39="-","",IFERROR(VALUE(F39),"")) | BQ39: =IF(R39="-",1,0) -> 1
A40: JQI1371 | B40: R5495 | C40: ROTA TRANSPORTES - ITABUNA | E40: 46273 | F40: 0.00 | G40: 0.95377315 | H40: 0 | I40: 0 | J40: 0 | K40: 0 | L40: 0 | M40: 0 | N40: 0 | O40: 0 | P40: 0 | Q40: - | R40: - | S40: 0 | T40: 0 | U40: 0 | V40: 0 | W40: 0 | X40: 0 | Y40: 0 | Z40: 0 | AA40: 0 | AB40: 0 | AC40: Rua K | AD40: Rua K | AE40: 18530.35 | AF40: 18530.35 | AG40: 0 | AH40: 0.026747685 | AI40: 0 | AJ40: 0 | AK40: 0 | AL40: 0 | AM40: N/A | AN40: 0 | AO40: 0 | AP40: 0 | AQ40: 0 | AR40: 0 | AS40: 0 | AT40: 0 | AU40: 0 | AV40: 0 | AW40: 0 | AX40: 0 | AY40: 0 | AZ40: 0 | BA40: 0 | BB40: 0 | BC40: 0 | BD40: 0 | BE40: 0 | BF40: 0 | BG40: 0 | BH40: 0 | BI40: 0 | BJ40: 0 | BK40: 0 | BM40: =IFERROR(VALUE(F40),"") -> 0 | BN40: =IF(R40="-","",IFERROR(VALUE(LEFT(Q40,LEN(Q40)-2)),"")) | BO40: =IF(R40="-","",IFERROR(VALUE(LEFT(R40,LEN(R40)-5)),"")) | BP40: =IF(R40="-","",IFERROR(VALUE(F40),"")) | BQ40: =IF(R40="-",1,0) -> 1
...

Sheet Base_Frota
A1: FROTA BASE
A2: Prefixo | B2: Placa | C2: Empresa | D2: Tipo | E2: FB | F2: Ano | G2: Unidade Operacional | H2: SETOR OU NOP | I2: Linha
A3: R7565 | B3: OZT0656 | C3: ROTA | D3: ÔNIBUS | E3: MBB | F3: 2015 | G3: RT/Itabuna | H3: ITABUNA | I3: ITABUNA X CONQUISTA X ITAPENGA X CANES
A4: R10185 | B4: OZG6088 | C4: ROTA | D4: ÔNIBUS | E4: Volvo | F4: 2014 | G4: RT/Itabuna | H4: CONQUISTA | I4: ESCOLAR EM VIT. DA CONQUISTA ( 1050 R )
A5: R10195 | B5: OZI2D57 | C5: ROTA | D5: ÔNIBUS | E5: MBB | F5: 2014 | G5: RT/Itabuna | H5: ITABUNA | I5: ITABUNA / PAU BRASIL IRIZAR R
A6: R10245 | B6: OZF2403 | C6: ROTA | D6: ÔNIBUS | E6: Volvo | F6: 2014 | G6: RT/Itabuna | H6: ITABUNA | I6: RESERVA ITABUNA (OF) - VOLVO
A7: R8905 | B7: SJS2J74 | C7: ROTA | D7: ÔNIBUS | E7: MBB | F7: 2024 | G7: RT/Itabuna | H7: CONQUISTA | I7: MINA NACIONAL GRAFITE - PEDRA AZUL - MG
A8: R10345 | B8: PJT1670 | C8: ROTA | D8: ÔNIBUS | E8: MBB | F8: 2016 | G8: RT/Itabuna | H8: ILHÉUS | I8: HOTEL - CANABRAVA ILHÉUS (1200 RS)
A9: R10355 | B9: PJT0511 | C9: ROTA | D9: ÔNIBUS | E9: MBB | F9: 2016 | G9: RT/Itabuna | H9: ILHÉUS | I9: HOTEL - CANABRAVA ILHÉUS (1200 RS)
A10: R10365 | B10: PJT7012 | C10: ROTA | D10: ÔNIBUS | E10: MBB | F10: 2016 | G10: RT/Itabuna | H10: ILHÉUS | I10: HOTEL - CANABRAVA ILHÉUS (1200 RS)
A11: R10375 | B11: PJT3877 | C11: ROTA | D11: ÔNIBUS | E11: MBB | F11: 2016 | G11: RT/Itabuna | H11: ILHÉUS | I11: HOTEL - CANABRAVA ILHÉUS (1200 RS)
A12: R10385 | B12: PKC5996 | C12: ROTA | D12: ÔNIBUS | E12: Volvo | F12: 2016 | G12: RT/Itabuna | H12: ILHÉUS | I12: HOTEL - CANABRAVA ILHÉUS 1200 B310R
A13: R10405 | B13: PKC5310 | C13: ROTA | D13: ÔNIBUS | E13: Volvo | F13: 2016 | G13: RT/Itabuna | H13: ITABUNA | I13: RESERVA ITABUNA 1200 B310R
A14: R10415 | B14: GGJ8C22 | C14: ROTA | D14: ÔNIBUS | E14: MBB | F14: 2016 | G14: RT/Itabuna | H14: CONQUISTA | I14: ESCOLAR EM VIT. DA CONQUISTA (DIANTEIRO) - MB
... A49: R7075 | B49: OUR3954 | C49: ROTA | D49: ÔNIBUS | E49: MBB | F49: 2012 | G49: RT/Itabuna | H49: ITABUNA | I49: ITABUNA / ILHEUS
A50: R7085 | B50: 115326 | C50: ROTA | D50: ÔNIBUS | E50: MBB | F50: 2012 | G50: RT/Itabuna | H50: ITABUNA | I50: ITABUNA / ILHEUS
A51: R7095 | B51: OUR7533 | C51: ROTA | D51: ÔNIBUS | E51: MBB | F51: 2012 | G51: RT/Itabuna | H51: ILHÉUS | I51: ILHEUS / ITABUNA
A52: R7105 | B52: OUR3686 | C52: ROTA | D52: ÔNIBUS | E52: MBB | F52: 2013 | G52: RT/Itabuna | H52: ILHÉUS | I52: ILHEUS / ITABUNA
A53: R7125 | B53: OUR3707 | C53: ROTA | D53: ÔNIBUS | E53: MBB | F53: 2012 | G53: RT/Itabuna | H53: ITABUNA | I53: ITABUNA X OLIVENÇA C/ CATRACA
A54: R7145 | B54: OUR9200 | C54: ROTA | D54: ÔNIBUS | E54: MBB | F54: 2012 | G54: RT/Itabuna | H54: ITABUNA | I54: ITABUNA / ITAPITANGA
A55: R7155 | B55: OUR8149 | C55: ROTA | D55: ÔNIBUS | E55: MBB | F55: 2012 | G55: RT/Itabuna | H55: ITABUNA | I55: ALMADINA X ITABUNA E ILHÉUS
A56: R7175 | B56: OZM4852 | C56: ROTA | D56: ÔNIBUS | E56: MBB | F56: 2013 | G56: RT/Itabuna | H56: ILHÉUS | I56: ILHÉUS / CONQUISTA 06:00/16:30
A57: R7415 | B57: OZV6244 | C57: ROTA | D57: ÔNIBUS | E57: MBB | F57: 2014 | G57: RT/Itabuna | H57: ITABUNA | I57: RESERVA ITABUNA - URBANO
A58: R7435 | B58: OZV9425 | C58: ROTA | D58: ÔNIBUS | E58: MBB | F58: 2014 | G58: RT/Itabuna | H58: ITABUNA | I58: RESERVA ITABUNA - URBANO
A59: R7445 | B59: OZV2987 | C59: ROTA | D59: ÔNIBUS | E59: MBB | F59: 2014 | G59: RT/Itabuna | H59: ITABUNA | I59: RESERVA ITABUNA - URBANO
A60: R8695 | B60: RPV3E20 | C60: ROTA | D60: ÔNIBUS | E60: MBB | F60: 2023 | G60: RT/Itabuna | H60: CONQUISTA | I60: ESCOLAR EM VIT. DA CONQUISTA
A61: R7465 | B61: OZV5174 | C61: ROTA | D61: ÔNIBUS | E61: MBB | F61: 2014 | G61: RT/Itabuna | H61: ITABUNA | I61: RESERVA ITABUNA
A62: R7475 | B62: OZT5781 | C62: ROTA | D62: ÔNIBUS | E62: MBB | F62: 2015 | G62: RT/Itabuna | H62: ILHÉUS | I62: RESERVA EM ILHÉUS
... A74: R7745 | B74: PKN8524 | C74: ROTA | D74: ÔNIBUS | E74: MBB | F74: 2015 | G74: RT/Itabuna | H74: ITABUNA | I74: RESERVA ITABUNA
A75: R5365 | B75: SJP4A43 | C75: ROTA | D75: ÔNIBUS | E75: MBB | F75: 2014 | G75: RT/Itabuna | H75: ITABUNA
A76: R8035 | B76: PLG3095 | C76: ROTA | D76: ÔNIBUS | E76: MBB | F76: 2019 | G76: RT/Itabuna | H76: CONQUISTA | I76: ESCOLAR EM VIT. DA CONQUISTA
A77: R10295 | B77: PKE7365 | C77: ROTA | D77: ÔNIBUS | E77: Volvo | F77: 2016 | G77: RT/Itabuna | H77: ITABUNA | I77: RESERVA EM ITABUNA (1200 VOLVO)
A78: R10525 | B78: PLZ9F44 | C78: ROTA | D78: ÔNIBUS | E78: Volvo | F78: 2020 | G78: RT/Itabuna | H78: ITABUNA | I78: RESERVA EM ITABUNA
A79: R8515 | B79: RPK0J26 | C79: ROTA | D79: ÔNIBUS | E79: MBB | F79: 2023 | G79: RT/Itabuna | H79: ITABUNA | I79: P. SEGURO 11:00 X ITACARÉ(13:00)- ITN 08:00-ITC 05:15)
A80: R8525 | B80: RPK0B75 | C80: ROTA | D80: ÔNIBUS | E80: MBB | F80: 2023 | G80: RT/Itabuna | H80: ITABUNA | I80: P. SEGURO (11:00 X ITACARÉ(13:00)- ITN 08:00-ITC 05:15)
A81: R10515 | B81: PLH4088 | C81: ROTA | D81: ÔNIBUS | E81: Volvo | F81: 2019 | G81: RT/Itabuna | H81: ITABUNA | I81: RESERVA EM ITABUNA (BUSCAR B360 R VOLVO)
A82: R8705 | B82: RPV1G14 | C82: ROTA | D82: ÔNIBUS | E82: MBB | F82: 2023 | G82: RT/Itabuna | H82: CONQUISTA | I82: ESCOLAR EM VIT. DA CONQUISTA
A83: R8715 | B83: SJN0C19 | C83: ROTA | D83: ÔNIBUS | E83: MBB | F83: 2024 | G83: RT/Itabuna | H83: CONQUISTA | I83: ESCOLAR EM VIT. DA CONQUISTA
A84: R8725 | B84: SJN2E11 | C84: ROTA | D84: ÔNIBUS | E84: MBB | F84: 2024 | G84: RT/Itabuna | H84: ILHÉUS | I84: A SERVIÇO DA BARRY CALLEBAUT - EM ILHÉUS
A85: R8755 | B85: SJN4F98 | C85: ROTA | D85: ÔNIBUS | E85: MBB | F85: 2024 | G85: RT/Itabuna | H85: ITABUNA | I85: A SERVIÇO DA BARRY CALLEBAUT - EM ITABUNA
...

Sheet Metas
B2: METAS E PARÂMETROS — GESTÃO DE MÉDIA DE COMBUSTÍVEL
B4: Preço médio do diesel (R$/L) | D4: 6 | E4: << ATUALIZAR com o preço real pago (não fornecido na base) >>
B6: Metas de eficiência por Modelo/Fabricante × Unidade Operacional (Setor)
B7: Meta inicial sugerida = mediana do km/L real dos veículos válidos do próprio grupo, apurada nesta base (08/09 a 14/09/2026). Ajuste manualmente para a meta oficial da empresa quando disponível.
B9: Fabricante/Modelo (FB) | C9: Unidade Operacional (Setor) | D9: Nº de veículos na Base_Frota | E9: Km/L real do grupo no período (agregado) | F9: Meta (Km/L) — editável | G9: Fonte da meta
B10: MBB | C10: CONQUISTA | D10: 16 | E10: 2.59 | F10: 3.24 | G10: Mediana do grupo (sugestão inicial) — substituir por meta oficial
B11: MBB | C11: ILHÉUS | D11: 21 | E11: 2.92 | F11: 2.84 | G11: Mediana do grupo (sugestão inicial) — substituir por meta oficial
B12: MBB | C12: ITABUNA | D12: 43 | E12: 3.11 | F12: 3.02 | G12: Mediana do grupo (sugestão inicial) — substituir por meta oficial
B13: Volvo | C13: CONQUISTA | D13: 2 | E13: 2.88 | F13: 2.91 | G13: Mediana do grupo (sugestão inicial) — substituir por meta oficial
B14: Volvo | C14: ILHÉUS | D14: 1 | E14: Sem dados no período | G14: Sem veículos com reporte numérico no período
B15: Volvo | C15: ITABUNA | D15: 6 | E15: 2.41 | F15: 4.61 | G15: Mediana do grupo (sugestão inicial) — substituir por meta oficial

Sheet Analise_Consumo
A1: GESTÃO DE MÉDIA DE COMBUSTÍVEL — ANÁLISE POR VEÍCULO (km/L real = km ÷ litros, não média das médias)
A2: km/L real calculado apenas com os dias em que a telemetria reportou número (média ≠ "-"), para não distorcer o indicador com dias sem medição. Base: Boletim 08/09 a 14/09/2026.
A4: Prefixo | B4: Placa | C4: Fabricante/Modelo | D4: Setor/UO | E4: Classificação de reporte | F4: Km totais (todos os dias) | G4: Km em dias com reporte | H4: Litros em dias com reporte | I4: Dias com reporte | J4: Dias com tracinho | K4: Km/L real | L4: Meta (Km/L) | M4: Desvio vs meta (%) | N4: Status | O4: Preço diesel (R$/L) | P4: Custo por Km (R$) | Q4: Custo total no período (R$) | R4: Economia potencial (L) | S4: Economia potencial (R$)
A5: R10175 | B5: OZG5113 | C5: Volvo | D5: CONQUISTA | E5: Deixou de reportar | F5: =SUMIFS('Boletim_do_Veiculo_2026-09-08_2'!$BM:$BM,'Boletim_do_Veiculo_2026-09-08_2'!$B:$B,$A5) -> 321.58 | G5: =SUMIFS('Boletim_do_Veiculo_2026-09-08_2'!$BP:$BP,'Boletim_do_Veiculo_2026-09-08_2'!$B:$B,$A5) -> 321.54 | H5: =SUMIFS('Boletim_do_Veiculo_2026-09-08_2'!$BN:$BN,'Boletim_do_Veiculo_2026-09-08_2'!$B:$B,$A5) -> 110.5 | I5: =COUNTIFS('Boletim_do_Veiculo_2026-09-08_2'!$B:$B,$A5,'Boletim_do_Veiculo_2026-09-08_2'!$R:$R,"<>-") -> 4 | J5: =COUNTIFS('Boletim_do_Veiculo_2026-09-08_2'!$B:$B,$A5,'Boletim_do_Veiculo_2026-09-08_2'!$R:$R,"-") -> 1 | K5: =IF(H5=0,"Sem dados",G5/H5) -> 2.9098643 | L5: =IFERROR(INDEX(Metas!$F$10:$F$15,MATCH(1,INDEX((Metas!$B$10:$B$15=C5)*(Metas!$C$10:$C$15=D5),0),0)),"") -> 2.91 | M5: =IF(OR(K5="Sem dados",L5="",L5=0),"",(K5-L5)/L5) -> -4.6648318e-05 | N5: =IF(K5="Sem dados","Sem dados suficientes",IF(M5="","Sem meta definida",IF(M5>=0.02,"Acima da meta",IF(M5<=-0.1,"Crítico: abaixo da meta",IF(M5<0,"Abaixo da meta","Na meta"))))) -> Abaixo da meta | O5: =Metas!$D$4 -> 6 | P5: =IF(K5="Sem dados","",IFERROR(O5/K5,"Km=0 c/ consumo>0 (ver nota)")) -> 2.0619519 | Q5: =H5*O5 -> 663 | R5: =IF(OR(K5="Sem dados",L5="",L5=0,K5>=L5),0,H5-(G5/L5)) -> 0.0051546392 | S5: =R5*O5 -> 0.030927835
A6: R10185 | B6: OZG6088 | C6: Volvo | D6: CONQUISTA | E6: Deixou de reportar | F6: =SUMIFS('Boletim_do_Veiculo_2026-09-08_2'!$BM:$BM,'Boletim_do_Veiculo_2026-09-08_2'!$B:$B,$A6) -> 0 | G6: =SUMIFS('Boletim_do_Veiculo_2026-09-08_2'!$BP:$BP,'Boletim_do_Veiculo_2026-09-08_2'!$B:$B,$A6) -> 0 | H6: =SUMIFS('Boletim_do_Veiculo_2026-09-08_2'!$BN:$BN,'Boletim_do_Veiculo_2026-09-08_2'!$B:$B,$A6) -> 1.08 | I6: =COUNTIFS('Boletim_do_Veiculo_2026-09-08_2'!$B:$B,$A6,'Boletim_do_Veiculo_2026-09-08_2'!$R:$R,"<>-") -> 3 | J6: =COUNTIFS('Boletim_do_Veiculo_2026-09-08_2'!$B:$B,$A6,'Boletim_do_Veiculo_2026-09-08_2'!$R:$R,"-") -> 2 | K6: =IF(H6=0,"Sem dados",G6/H6) -> 0 | L6: =IFERROR(INDEX(Metas!$F$10:$F$15,MATCH(1,INDEX((Metas!$B$10:$B$15=C6)*(Metas!$C$10:$C$15=D6),0),0)),"") -> 2.91 | M6: =IF(OR(K6="Sem dados",L6="",L6=0),"",(K6-L6)/L6) -> -1 | N6: =IF(K6="Sem dados","Sem dados suficientes",IF(M6="","Sem meta definida",IF(M6>=0.02,"Acima da meta",IF(M6<=-0.1,"Crítico: abaixo da meta",IF(M6<0,"Abaixo da meta","Na meta"))))) -> Crítico: abaixo da meta | O6: =Metas!$D$4 -> 6 | P6: =IF(K6="Sem dados","",IFERROR(O6/K6,"Km=0 c/ consumo>0 (ver nota)")) -> Km=0 c/ consumo>0 (ver nota) | Q6: =H6*O6 -> 6.48 | R6: =IF(OR(K6="Sem dados",L6="",L6=0,K6>=L6),0,H6-(G6/L6)) -> 1.08 | S6: =R6*O6 -> 6.48
A7: R10195 | B7: OZI2D57 | C7: MBB | D7: ITABUNA | E7: Reporte contínuo | F7: =SUMIFS('Boletim_do_Veiculo_2026-09-08_2'!$BM:$BM,'Boletim_do_Veiculo_2026-09-08_2'!$B:$B,$A7) -> 1615.15 | G7: =SUMIFS('Boletim_do_Veiculo_2026-09-08_2'!$BP:$BP,'Boletim_do_Veiculo_2026-09-08_2'!$B:$B,$A7) -> 1615.15 | H7: =SUMIFS('Boletim_do_Veiculo_2026-09-08_2'!$BN:$BN,'Boletim_do_Veiculo_2026-09-08_2'!$B:$B,$A7) -> 593.39 | I7: =COUNTIFS('Boletim_do_Veiculo_2026-09-08_2'!$B:$B,$A7,'Boletim_do_Veiculo_2026-09-08_2'!$R:$R,"<>-") -> 7 | J7: =COUNTIFS('Boletim_do_Veiculo_2026-09-08_2'!$B:$B,$A7,'Boletim_do_Veiculo_2026-09-08_2'!$R:$R,"-") -> 0 | K7: =IF(H7=0,"Sem dados",G7/H7) -> 2.721903 | L7: =IFERROR(INDEX(Metas!$F$10:$F$15,MATCH(1,INDEX((Metas!$B$10:$B$15=C7)*(Metas!$C$10:$C$15=D7),0),0)),"") -> 3.02 | M7: =IF(OR(K7="Sem dados",L7="",L7=0),"",(K7-L7)/L7) -> -0.098707628 | N7: =IF(K7="Sem dados","Sem dados suficientes",IF(M7="","Sem meta definida",IF(M7>=0.02,"Acima da meta",IF(M7<=-0.1,"Crítico: abaixo da meta",IF(M7<0,"Abaixo da meta","Na meta"))))) -> Abaixo da meta | O7: =Metas!$D$4 -> 6 | P7: =IF(K7="Sem dados","",IFERROR(O7/K7,"Km=0 c/ consumo>0 (ver nota)")) -> 2.2043402 | Q7: =H7*O7 -> 3560.34 | R7: =IF(OR(K7="Sem dados",L7="",L7=0,K7>=L7),0,H7-(G7/L7)) -> 58.572119 | S7: =R7*O7 -> 351.43272
A8: R10245 | B8: OZF2403 | C8: Volvo | D8: ITABUNA | E8: Reporte contínuo | F8: =SUMIFS('Boletim_do_Veiculo_2026-09-08_2'!$BM:$BM,'Boletim_do_Veiculo_2026-09-08_2'!$B:$B,$A8) -> 0 | G8: =SUMIFS('Boletim_do_Veiculo_2026-09-08_2'!$BP:$BP,'Boletim_do_Veiculo_2026-09-08_2'!$B:$B,$A8) -> 0 | H8: =SUMIFS('Boletim_do_Veiculo_2026-09-08_2'!$BN:$BN,'Boletim_do_Veiculo_2026-09-08_2'!$B:$B,$A8) -> 1.26 | I8: =COUNTIFS('Boletim_do_Veiculo_2026-09-08_2'!$B:$B,$A8,'Boletim_do_Veiculo_2026-09-08_2'!$R:$R,"<>-") -> 3 | J8: =COUNTIFS('Boletim_do_Veiculo_2026-09-08_2'!$B:$B,$A8,'Boletim_do_Veiculo_2026-09-08_2'!$R:$R,"-") -> 0 | K8: =IF(H8=0,"Sem dados",G8/H8) -> 0 | L8: =IFERROR(INDEX(Metas!$F$10:$F$15,MATCH(1,INDEX((Metas!$B$10:$B$15=C8)*(Metas!$C$10:$C$15=D8),0),0)),"") -> 4.61 | M8: =IF(OR(K8="Sem dados",L8="",L8=0),"",(K8-L8)/L8) -> -1 | N8: =IF(K8="Sem dados","Sem dados suficientes",IF(M8="","Sem meta definida",IF(M8>=0.02,"Acima da meta",IF(M8<=-0.1,"Crítico: abaixo da meta",IF(M8<0,"Abaixo da meta","Na meta"))))) -> Crítico: abaixo da meta | O8: =Metas!$D$4 -> 6 | P8: =IF(K8="Sem dados","",IFERROR(O8/K8,"Km=0 c/ consumo>0 (ver nota)")) -> Km=0 c/ consumo>0 (ver nota) | Q8: =H8*O8 -> 7.56 | R8: =IF(OR(K8="Sem dados",L8="",L8=0,K8>=L8),0,H8-(G8/L8)) -> 1.26 | S8: =R8*O8 -> 7.56
A9: R10295 | B9: PKE7365 | C9: Volvo | D9: ITABUNA | E9: Reporte contínuo | F9: =SUMIFS('Boletim_do_Veiculo_2026-09-08_2'!$BM:$BM,'Boletim_do_Veiculo_2026-09-08_2'!$B:$B,$A9) -> 1.37 | G9: =SUMIFS('Boletim_do_Veiculo_2026-09-08_2'!$BP:$BP,'Boletim_do_Veiculo_2026-09-08_2'!$B:$B,$A9) -> 1.37 | H9: =SUMIFS('Boletim_do_Veiculo_2026-09-08_2'!$BN:$BN,'Boletim_do_Veiculo_2026-09-08_2'!$B:$B,$A9) -> 834.42 | I9: =COUNTIFS('Boletim_do_Veiculo_2026-09-08_2'!$B:$B,$A9,'Boletim_do_Veiculo_2026-09-08_2'!$R:$R,"<>-") -> 7 | J9: =COUNTIFS('Boletim_do_Veiculo_2026-09-08_2'!$B:$B,$A9,'Boletim_do_Veiculo_2026-09-08_2'!$R:$R,"-") -> 0 | K9: =IF(H9=0,"Sem dados",G9/H9) -> 0.001641859 | L9: =IFERROR(INDEX(Metas!$F$10:$F$15,MATCH(1,INDEX((Metas!$B$10:$B$15=C9)*(Metas!$C$10:$C$15=D9),0),0)),"") -> 4.61 | M9: =IF(OR(K9="Sem dados",L9="",L9=0),"",(K9-L9)/L9) -> -0.99964385 | N9: =IF(K9="Sem dados","Sem dados suficientes",IF(M9="","Sem meta definida",IF(M9>=0.02,"Acima da meta",IF(M9<=-0.1,"Crítico: abaixo da meta",IF(M9<0,"Abaixo da meta","Na meta"))))) -> Crítico: abaixo da meta | O9: =Metas!$D$4 -> 6 | P9: =IF(K9="Sem dados","",IFERROR(O9/K9,"Km=0 c/ consumo>0 (ver nota)")) -> 3654.3942 | Q9: =H9*O9 -> 5006.52 | R9: =IF(OR(K9="Sem dados",L9="",L9=0,K9>=L9),0,H9-(G9/L9)) -> 834.12282 | S9: =R9*O9 -> 5004.7369
A10: R10355 | B10: PJT0511 | C10: MBB | D10: ILHÉUS | E10: Reporte contínuo | F10: =SUMIFS('Boletim_do_Veiculo_2026-09-08_2'!$BM:$BM,'Boletim_do_Veiculo_2026-09-08_2'!$B:$B,$A10) -> 861.59 | G10: =SUMIFS('Boletim_do_Veiculo_2026-09-08_2'!$BP:$BP,'Boletim_do_Veiculo_2026-09-08_2'!$B:$B,$A10) -> 861.59 | H10: =SUMIFS('Boletim_do_Veiculo_2026-09-08_2'!$BN:$BN,'Boletim_do_Veiculo_2026-09-08_2'!$B:$B,$A10) -> 315.55 | I10: =COUNTIFS('Boletim_do_Veiculo_2026-09-08_2'!$B:$B,$A10,'Boletim_do_Veiculo_2026-09-08_2'!$R:$R,"<>-") -> 7 | J10: =COUNTIFS('Boletim_do_Veiculo_2026-09-08_2'!$B:$B,$A10,'Boletim_do_Veiculo_2026-09-08_2'!$R:$R,"-") -> 0 | K10: =IF(H10=0,"Sem dados",G10/H10) -> 2.7304389 | L10: =IFERROR(INDEX(Metas!$F$10:$F$15,MATCH(1,INDEX((Metas!$B$10:$B$15=C10)*(Metas!$C$10:$C$15=D10),0),0)),"") -> 2.84 | M10: =IF(OR(K10="Sem dados",L10="",L10=0),"",(K10-L10)/L10) -> -0.038577846 | N10: =IF(K10="Sem dados","Sem dados suficientes",IF(M10="","Sem meta definida",IF(M10>=0.02,"Acima da meta",IF(M10<=-0.1,"Crítico: abaixo da meta",IF(M10<0,"Abaixo da meta","Na meta"))))) -> Abaixo da meta | O10: =Metas!$D$4 -> 6 | P10: =IF(K10="Sem dados","",IFERROR(O10/K10,"Km=0 c/ consumo>0 (ver nota)")) -> 2.1974489 | Q10: =H10*O10 -> 1893.3 | R10: =IF(OR(K10="Sem dados",L10="",L10=0,K10>=L10),0,H10-(G10/L10)) -> 12.173239 | S10: =R10*O10 -> 73.039437
A11: R10365 | B11: PJT7012 | C11: MBB | D11: ILHÉUS | E11: Reporte contínuo | F11: =SUMIFS('Boletim_do_Veiculo_2026-09-08_2'!$BM:$BM,'Boletim_do_Veiculo_2026-09-08_2'!$B:$B,$A11) -> 1738.37 | G11: =SUMIFS('Boletim_do_Veiculo_2026-09-08_2'!$BP:$BP,'Boletim_do_Veiculo_2026-09-08_2'!$B:$B,$A11) -> 1738.37 | H11: =SUMIFS('Boletim_do_Veiculo_2026-09-08_2'!$BN:$BN,'Boletim_do_Veiculo_2026-09-08_2'!$B:$B,$A11) -> 691.58 | I11: =COUNTIFS('Boletim_do_Veiculo_2026-09-08_2'!$B:$B,$A11,'Boletim_do_Veiculo_2026-09-08_2'!$R:$R,"<>-") -> 7 | J11: =COUNTIFS('Boletim_do_Veiculo_2026-09-08_2'!$B:$B,$A11,'Boletim_do_Veiculo_2026-09-08_2'!$R:$R,"-") -> 0 | K11: =IF(H11=0,"Sem dados",G11/H11) -> 2.513621 | L11: =IFERROR(INDEX(Metas!$F$10:$F$15,MATCH(1,INDEX((Metas!$B$10:$B$15=C11)*(Metas!$C$10:$C$15=D11),0),0)),"") -> 2.84 | M11: =IF(OR(K11="Sem dados",L11="",L11=0),"",(K11-L11)/L11) -> -0.11492219 | N11: =IF(K11="Sem dados","Sem dados suficientes",IF(M11="","Sem meta definida",IF(M11>=0.02,"Acima da meta",IF(M11<=-0.1,"Crítico: abaixo da meta",IF(M11<0,"Abaixo da meta","Na meta"))))) -> Crítico: abaixo da meta | O11: =Metas!$D$4 -> 6 | P11: =IF(K11="Sem dados","",IFERROR(O11/K11,"Km=0 c/ consumo>0 (ver nota)")) -> 2.3869947 | Q11: =H11*O11 -> 4149.48 | R11: =IF(OR(K11="Sem dados",L11="",L11=0,K11>=L11),0,H11-(G11/L11)) -> 79.477887 | S11: =R11*O11 -> 476.86732
